Workbook

Sheet 首页
B1: 护盾承受值 | C1: 每日护盾回复 | D1: mod护盾回复比例 | E1: 25级护盾回复比例 | F1: 合金花费 | G1: 泽洛花费 | I1: 尺寸 | J1: 合金维护费 | K1: 能量维护费
A2: 小型灵能护盾 | B2: 400 | C2: 2 | D2: =B2/C2 -> 200 | E2: 80 | F2: 41 | G2: 0.11 | I2: 小型 | J2: 0.114 | K2: 0.38
A3: 中型灵能护盾 | B3: 1200 | C3: 6 | D3: =B3/C3 -> 200 | E3: 80 | F3: 103 | G3: 0.22 | I3: 中型 | J3: 0.228 | K3: 0.76
A4: 大型灵能护盾 | B4: 3600 | C4: 18 | D4: =B4/C4 -> 200 | E4: 80 | F4: 258 | G4: 0.333 | I4: 大型 | J4: 0.456 | K4: 1.52
A5: 小型生物灵能护盾 | B5: 320 | C5: 4 | D5: =B5/C5 -> 80 | E5: 80 | F5: 41 | G5: 0.11
A6: 中型生物灵能护盾 | B6: 960 | C6: 12 | D6: =B6/C6 -> 80 | E6: 80 | F6: 103 | G6: 0.22 | I6: 硬化起始 | J6: 硬化每级增加 | K6: 科技花费
A7: 大型生物灵能护盾 | B7: 2880 | C7: 36 | D7: =B7/C7 -> 80 | E7: 80 | F7: 258 | G7: 0.333 | I7: 0.06 | J7: 0.01 | K7: 50000000
B11: 护盾承受值 | C11: 护盾buff | D11: 每日护盾回复比例 | E11: 25级护盾回复比例 | F11: 装甲值 | G11: 装甲护盾合计 | H11: 合金花费 | I11: 合金维护 | J11: 能量维护 | K11: 稀有文物 | L11: mod折扣
A12: 小型古代脉冲甲 | B12: 100 | C12: 100 | D12: =(B12+C12)/0.8 -> 250 | E12: 200 | F12: 160 | G12: =B12+F12+C12 -> 360 | H12: 35 | I12: 0.102 | J12: 0.51 | K12: 8 | L12: 0.5
A13: 中型古达脉冲甲 | B13: 300 | C13: 300 | D13: =(B13+C13)/2.4 -> 250 | E13: 200 | F13: 480 | G13: =B13+F13+C13 -> 1080 | H13: 88 | I13: 0.203 | J13: 1.02 | K13: 20 | L13: 0.5
A14: 大型古代脉冲甲 | B14: 900 | C14: 900 | D14: =(B14+C14)/7.2 -> 250 | E14: 200 | F14: 1440 | G14: =B14+F14+C14 -> 3240 | H14: 220 | I14: 0.405 | J14: 2.03 | K14: 50 | L14: 0.5
B16: 护盾承受值 | C16: 护盾buff | D16: 每日护盾回复比例 | E16: 25级护盾回复比例 | F16: 装甲值 | G16: 每日装甲回复 | H16: 装甲回复比例 | I16: 装甲护盾合计 | J16: 25级护甲回复比例 | K16: 船体值 | L16: 稀有文物 | M16: mod折扣
A17: 小型脉冲甲壳 | B17: 80 | C17: 80 | D17: =(C17+B17)/1 -> 160 | E17: 160 | F17: 128 | G17: 0.16 | H17: =F17/G17 -> 800 | I17: =F17+C17+B17 -> 288 | J17: 800 | K17: 13 | L17: 8 | M17: 0.5
A18: 中型脉冲甲壳 | B18: 240 | C18: 240 | D18: =(C18+B18)/3 -> 160 | E18: 160 | F18: 384 | G18: 0.48 | H18: =F18/G18 -> 800 | I18: =F18+C18+B18 -> 864 | J18: 800 | K18: 39 | L18: 20 | M18: 0.5
A19: 大型脉冲甲壳 | B19: 720 | C19: 720 | D19: =(C19+B19)/9 -> 160 | E19: 160 | F19: 1152 | G19: 1.44 | H19: =F19/G19 -> 800 | I19: =F19+C19+B19 -> 2592 | J19: 800 | K19: 117 | L19: 50 | M19: 0.5
B23: 装甲值 | C23: 合金造价 | D23: mod折扣 | E23: mod活体金属 | F23: mod纳米
A24: 小型龙鳞甲 | B24: 325 | C24: 41 | D24: 0.8 | E24: 1 | F24: 0.5
A25: 中型龙鳞甲 | B25: 975 | C25: 103 | D25: 0.8 | E25: 2 | F25: 1
A26: 大型龙鳞甲 | B26: 2925 | C26: 258 | D26: 0.8 | E26: 3 | F26: 1.5
B30: 装甲值 | C30: 装甲每日回复 | D30: 装甲回复比例 | E30: mod装甲回复比例 | F30: 船体值 | G30: 合金造价 | H30: mod合金比例 | I30: mod食物比例 | J30: 合金维护 | K30: 能量维护
A31: 小型龙鳞甲壳 | B31: 260 | C31: 0.325 | D31: =B2/C2 -> 200 | E31: 200 | F31: 26 | G31: 41 | H31: 0.5 | I31: 0.5 | J31: 0.102 | K31: 0.51
A32: 中型龙鳞甲壳 | B32: 780 | C32: 0.975 | D32: =B3/C3 -> 200 | E32: 200 | F32: 78 | G32: 103 | H32: 0.5 | I32: 0.5 | J32: 0.203 | K32: 1.02
A33: 大型龙鳞甲壳 | B33: 2340 | C33: 2.925 | D33: =B4/C4 -> 200 | E33: 200 | F33: 234 | G33: 258 | H33: 0.5 | I33: 0.5 | J33: 0.405 | K33: 2.03
B41: 每合金防护 | C41: 25恢复比例 | D41: 每合金总防护(1月)
A42: 灵能护盾
A43: 生物灵能护盾
A44: 古代脉冲甲
A45: 脉冲甲壳
A46: 龙鳞甲
A47: 龙鳞甲壳

Sheet 通用指标
A1: 级别 | B1: 尺寸 | C1: 小型护盾组件合金维护费 | D1: 数值 | E1: 小型护盾组件能量维护费 | F1: 数值 | G1: 小型装甲合金维护费 | H1: 数值 | I1: 小型装甲能量维护费 | J1: 数值 | K1: 小型组件护盾船伤害减免 | L1: 数值
A2: 2 | B2: 小型 | C2: shield_s2_alloys_upkeep_mod | D2: =ROUND((ROW()-ROW(D$1)-1)*0.1*首页!$J$2+首页!$J$2,2) -> 0.11 | E2: shield_s2_alloys_energy_mod | F2: =ROUNDUP((ROW()-ROW(F$1))*0.1*首页!$K$2+首页!$K$2,2) -> 0.42 | G2: armor_s2_alloys_upkeep_mod | H2: =ROUND((ROW()-ROW(H$1))*0.1*首页!$I$12+首页!$I$12,2) -> 0.11 | I2: armor_s2_alloys_energy_mod | J2: =ROUND((ROW()-ROW(J$1))*0.1*首页!$J$12+首页!$J$12,2) -> 0.56 | K2: damage_mod_reduction_s2 | L2: 0
A3: 3 | B3: 小型 | C3: shield_s3_alloys_upkeep_mod | D3: =ROUND((ROW()-ROW(D$1)-1)*0.1*首页!$J$2+首页!$J$2,2) -> 0.13 | E3: shield_s3_alloys_energy_mod | F3: =ROUNDUP((ROW()-ROW(F$1))*0.1*首页!$K$2+首页!$K$2,2) -> 0.46 | G3: armor_s3_alloys_upkeep_mod | H3: =ROUND((ROW()-ROW(H$1))*0.1*首页!$I$12+首页!$I$12,2) -> 0.12 | I3: armor_s3_alloys_energy_mod | J3: =ROUND((ROW()-ROW(J$1))*0.1*首页!$J$12+首页!$J$12,2) -> 0.61 | K3: damage_mod_reduction_s3 | L3: 0
A4: 4 | B4: 小型 | C4: shield_s4_alloys_upkeep_mod | D4: =ROUND((ROW()-ROW(D$1)-1)*0.1*首页!$J$2+首页!$J$2,2) -> 0.14 | E4: shield_s4_alloys_energy_mod | F4: =ROUNDUP((ROW()-ROW(F$1))*0.1*首页!$K$2+首页!$K$2,2) -> 0.5 | G4: armor_s4_alloys_upkeep_mod | H4: =ROUND((ROW()-ROW(H$1))*0.1*首页!$I$12+首页!$I$12,2) -> 0.13 | I4: armor_s4_alloys_energy_mod | J4: =ROUND((ROW()-ROW(J$1))*0.1*首页!$J$12+首页!$J$12,2) -> 0.66 | K4: damage_mod_reduction_s4 | L4: 0
A5: 5 | B5: 小型 | C5: shield_s5_alloys_upkeep_mod | D5: =ROUND((ROW()-ROW(D$1)-1)*0.1*首页!$J$2+首页!$J$2,2) -> 0.15 | E5: shield_s5_alloys_energy_mod | F5: =ROUNDUP((ROW()-ROW(F$1))*0.1*首页!$K$2+首页!$K$2,2) -> 0.54 | G5: armor_s5_alloys_upkeep_mod | H5: =ROUND((ROW()-ROW(H$1))*0.1*首页!$I$12+首页!$I$12,2) -> 0.14 | I5: armor_s5_alloys_energy_mod | J5: =ROUND((ROW()-ROW(J$1))*0.1*首页!$J$12+首页!$J$12,2) -> 0.71 | K5: damage_mod_reduction_s5 | L5: 0
A6: 6 | B6: 小型 | C6: shield_s6_alloys_upkeep_mod | D6: =ROUND((ROW()-ROW(D$1)-1)*0.1*首页!$J$2+首页!$J$2,2) -> 0.16 | E6: shield_s6_alloys_energy_mod | F6: =ROUNDUP((ROW()-ROW(F$1))*0.1*首页!$K$2+首页!$K$2,2) -> 0.57 | G6: armor_s6_alloys_upkeep_mod | H6: =ROUND((ROW()-ROW(H$1))*0.1*首页!$I$12+首页!$I$12,2) -> 0.15 | I6: armor_s6_alloys_energy_mod | J6: =ROUND((ROW()-ROW(J$1))*0.1*首页!$J$12+首页!$J$12,2) -> 0.77 | K6: damage_mod_reduction_s6 | L6: 0
A7: 7 | B7: 小型 | C7: shield_s7_alloys_upkeep_mod | D7: =ROUND((ROW()-ROW(D$1)-1)*0.1*首页!$J$2+首页!$J$2,2) -> 0.17 | E7: shield_s7_alloys_energy_mod | F7: =ROUNDUP((ROW()-ROW(F$1))*0.1*首页!$K$2+首页!$K$2,2) -> 0.61 | G7: armor_s7_alloys_upkeep_mod | H7: =ROUND((ROW()-ROW(H$1))*0.1*首页!$I$12+首页!$I$12,2) -> 0.16 | I7: armor_s7_alloys_energy_mod | J7: =ROUND((ROW()-ROW(J$1))*0.1*首页!$J$12+首页!$J$12,2) -> 0.82 | K7: damage_mod_reduction_s7 | L7: 0
A8: 8 | B8: 小型 | C8: shield_s8_alloys_upkeep_mod | D8: =ROUND((ROW()-ROW(D$1)-1)*0.1*首页!$J$2+首页!$J$2,2) -> 0.18 | E8: shield_s8_alloys_energy_mod | F8: =ROUNDUP((ROW()-ROW(F$1))*0.1*首页!$K$2+首页!$K$2,2) -> 0.65 | G8: armor_s8_alloys_upkeep_mod | H8: =ROUND((ROW()-ROW(H$1))*0.1*首页!$I$12+首页!$I$12,2) -> 0.17 | I8: armor_s8_alloys_energy_mod | J8: =ROUND((ROW()-ROW(J$1))*0.1*首页!$J$12+首页!$J$12,2) -> 0.87 | K8: damage_mod_reduction_s8 | L8: 0
A9: 9 | B9: 小型 | C9: shield_s9_alloys_upkeep_mod | D9: =ROUND((ROW()-ROW(D$1)-1)*0.1*首页!$J$2+首页!$J$2,2) -> 0.19 | E9: shield_s9_alloys_energy_mod | F9: =ROUNDUP((ROW()-ROW(F$1))*0.1*首页!$K$2+首页!$K$2,2) -> 0.69 | G9: armor_s9_alloys_upkeep_mod | H9: =ROUND((ROW()-ROW(H$1))*0.1*首页!$I$12+首页!$I$12,2) -> 0.18 | I9: armor_s9_alloys_energy_mod | J9: =ROUND((ROW()-ROW(J$1))*0.1*首页!$J$12+首页!$J$12,2) -> 0.92 | K9: damage_mod_reduction_s9 | L9: 0
A10: 10 | B10: 小型 | C10: shield_s10_alloys_upkeep_mod | D10: =ROUND((ROW()-ROW(D$1)-1)*0.1*首页!$J$2+首页!$J$2,2) -> 0.21 | E10: shield_s10_alloys_energy_mod | F10: =ROUNDUP((ROW()-ROW(F$1))*0.1*首页!$K$2+首页!$K$2,2) -> 0.73 | G10: armor_s10_alloys_upkeep_mod | H10: =ROUND((ROW()-ROW(H$1))*0.1*首页!$I$12+首页!$I$12,2) -> 0.19 | I10: armor_s10_alloys_energy_mod | J10: =ROUND((ROW()-ROW(J$1))*0.1*首页!$J$12+首页!$J$12,2) -> 0.97 | K10: damage_mod_reduction_s10 | L10: 0
A11: 11 | B11: 小型 | C11: shield_s11_alloys_upkeep_mod | D11: =ROUND((ROW()-ROW(D$1)-1)*0.1*首页!$J$2+首页!$J$2,2) -> 0.22 | E11: shield_s11_alloys_energy_mod | F11: =ROUNDUP((ROW()-ROW(F$1))*0.1*首页!$K$2+首页!$K$2,2) -> 0.76 | G11: armor_s11_alloys_upkeep_mod | H11: =ROUND((ROW()-ROW(H$1))*0.1*首页!$I$12+首页!$I$12,2) -> 0.2 | I11: armor_s11_alloys_energy_mod | J11: =ROUND((ROW()-ROW(J$1))*0.1*首页!$J$12+首页!$J$12,2) -> 1.02 | K11: damage_mod_reduction_s11 | L11: 0
A12: 12 | B12: 小型 | C12: shield_s12_alloys_upkeep_mod | D12: =ROUND((ROW()-ROW(D$1)-1)*0.1*首页!$J$2+首页!$J$2,2) -> 0.23 | E12: shield_s12_alloys_energy_mod | F12: =ROUNDUP((ROW()-ROW(F$1))*0.1*首页!$K$2+首页!$K$2,2) -> 0.8 | G12: armor_s12_alloys_upkeep_mod | H12: =ROUND((ROW()-ROW(H$1))*0.1*首页!$I$12+首页!$I$12,2) -> 0.21 | I12: armor_s12_alloys_energy_mod | J12: =ROUND((ROW()-ROW(J$1))*0.1*首页!$J$12+首页!$J$12,2) -> 1.07 | K12: damage_mod_reduction_s12 | L12: 0
A13: 13 | B13: 小型 | C13: shield_s13_alloys_upkeep_mod | D13: =ROUND((ROW()-ROW(D$1)-1)*0.1*首页!$J$2+首页!$J$2,2) -> 0.24 | E13: shield_s13_alloys_energy_mod | F13: =ROUNDUP((ROW()-ROW(F$1))*0.1*首页!$K$2+首页!$K$2,2) -> 0.84 | G13: armor_s13_alloys_upkeep_mod | H13: =ROUND((ROW()-ROW(H$1))*0.1*首页!$I$12+首页!$I$12,2) -> 0.22 | I13: armor_s13_alloys_energy_mod | J13: =ROUND((ROW()-ROW(J$1))*0.1*首页!$J$12+首页!$J$12,2) -> 1.12 | K13: damage_mod_reduction_s13 | L13: 0
... A25: 25 | B25: 小型 | C25: shield_s25_alloys_upkeep_mod | D25: =ROUND((ROW()-ROW(D$1)-1)*0.1*首页!$J$2+首页!$J$2,2) -> 0.38 | E25: shield_s25_alloys_energy_mod | F25: =ROUNDUP((ROW()-ROW(F$1))*0.1*首页!$K$2+首页!$K$2,2) -> 1.3 | G25: armor_s25_alloys_upkeep_mod | H25: =ROUND((ROW()-ROW(H$1))*0.1*首页!$I$12+首页!$I$12,2) -> 0.35 | I25: armor_s25_alloys_energy_mod | J25: =ROUND((ROW()-ROW(J$1))*0.1*首页!$J$12+首页!$J$12,2) -> 1.73 | K25: damage_mod_reduction_s25 | L25: 0
A27: 级别 | B27: 尺寸 | C27: 中型护盾组件能量维护费 | D27: 数值 | E27: 中型护盾组件能量维护费 | F27: 数值 | G27: 中型装甲合金维护费 | H27: 数值 | I27: 中型装甲能量维护费 | J27: 数值 | K27: 护盾船伤害减免 | L27: 数值
A28: 2 | B28: 中型 | C28: shield_m2_alloys_upkeep_mod | D28: =ROUND((ROW()-ROW(D$27))*0.1*首页!$J$3+首页!$J$3,2) -> 0.25 | E28: shield_m2_alloys_energy_mod | F28: =ROUNDUP((ROW()-ROW(F$27))*0.1*首页!$K$3+首页!$K$3,2) -> 0.84 | G28: armor_m2_alloys_upkeep_mod | H28: =ROUND((ROW()-ROW(H$27))*0.1*首页!$I$13+首页!$I$13,2) -> 0.22 | I28: armor_m2_alloys_energy_mod | J28: =ROUND((ROW()-ROW(J$27))*0.1*首页!$J$13+首页!$J$13,2) -> 1.12 | K28: damage_mod_reduction_m2 | L28: 0
A29: 3 | B29: 中型 | C29: shield_m3_alloys_upkeep_mod | D29: =ROUND((ROW()-ROW(D$27))*0.1*首页!$J$3+首页!$J$3,2) -> 0.27 | E29: shield_m3_alloys_energy_mod | F29: =ROUNDUP((ROW()-ROW(F$27))*0.1*首页!$K$3+首页!$K$3,2) -> 0.92 | G29: armor_m3_alloys_upkeep_mod | H29: =ROUND((ROW()-ROW(H$27))*0.1*首页!$I$13+首页!$I$13,2) -> 0.24 | I29: armor_m3_alloys_energy_mod | J29: =ROUND((ROW()-ROW(J$27))*0.1*首页!$J$13+首页!$J$13,2) -> 1.22 | K29: damage_mod_reduction_m3 | L29: 0
A30: 4 | B30: 中型 | C30: shield_m4_alloys_upkeep_mod | D30: =ROUND((ROW()-ROW(D$27))*0.1*首页!$J$3+首页!$J$3,2) -> 0.3 | E30: shield_m4_alloys_energy_mod | F30: =ROUNDUP((ROW()-ROW(F$27))*0.1*首页!$K$3+首页!$K$3,2) -> 0.99 | G30: armor_m4_alloys_upkeep_mod | H30: =ROUND((ROW()-ROW(H$27))*0.1*首页!$I$13+首页!$I$13,2) -> 0.26 | I30: armor_m4_alloys_energy_mod | J30: =ROUND((ROW()-ROW(J$27))*0.1*首页!$J$13+首页!$J$13,2) -> 1.33 | K30: damage_mod_reduction_m4 | L30: 0
A31: 5 | B31: 中型 | C31: shield_m5_alloys_upkeep_mod | D31: =ROUND((ROW()-ROW(D$27))*0.1*首页!$J$3+首页!$J$3,2) -> 0.32 | E31: shield_m5_alloys_energy_mod | F31: =ROUNDUP((ROW()-ROW(F$27))*0.1*首页!$K$3+首页!$K$3,2) -> 1.07 | G31: armor_m5_alloys_upkeep_mod | H31: =ROUND((ROW()-ROW(H$27))*0.1*首页!$I$13+首页!$I$13,2) -> 0.28 | I31: armor_m5_alloys_energy_mod | J31: =ROUND((ROW()-ROW(J$27))*0.1*首页!$J$13+首页!$J$13,2) -> 1.43 | K31: damage_mod_reduction_m5 | L31: 0
A32: 6 | B32: 中型 | C32: shield_m6_alloys_upkeep_mod | D32: =ROUND((ROW()-ROW(D$27))*0.1*首页!$J$3+首页!$J$3,2) -> 0.34 | E32: shield_m6_alloys_energy_mod | F32: =ROUNDUP((ROW()-ROW(F$27))*0.1*首页!$K$3+首页!$K$3,2) -> 1.14 | G32: armor_m6_alloys_upkeep_mod | H32: =ROUND((ROW()-ROW(H$27))*0.1*首页!$I$13+首页!$I$13,2) -> 0.3 | I32: armor_m6_alloys_energy_mod | J32: =ROUND((ROW()-ROW(J$27))*0.1*首页!$J$13+首页!$J$13,2) -> 1.53 | K32: damage_mod_reduction_m6 | L32: 0
A33: 7 | B33: 中型 | C33: shield_m7_alloys_upkeep_mod | D33: =ROUND((ROW()-ROW(D$27))*0.1*首页!$J$3+首页!$J$3,2) -> 0.36 | E33: shield_m7_alloys_energy_mod | F33: =ROUNDUP((ROW()-ROW(F$27))*0.1*首页!$K$3+首页!$K$3,2) -> 1.22 | G33: armor_m7_alloys_upkeep_mod | H33: =ROUND((ROW()-ROW(H$27))*0.1*首页!$I$13+首页!$I$13,2) -> 0.32 | I33: armor_m7_alloys_energy_mod | J33: =ROUND((ROW()-ROW(J$27))*0.1*首页!$J$13+首页!$J$13,2) -> 1.63 | K33: damage_mod_reduction_m7 | L33: 0
A34: 8 | B34: 中型 | C34: shield_m8_alloys_upkeep_mod | D34: =ROUND((ROW()-ROW(D$27))*0.1*首页!$J$3+首页!$J$3,2) -> 0.39 | E34: shield_m8_alloys_energy_mod | F34: =ROUNDUP((ROW()-ROW(F$27))*0.1*首页!$K$3+首页!$K$3,2) -> 1.3 | G34: armor_m8_alloys_upkeep_mod | H34: =ROUND((ROW()-ROW(H$27))*0.1*首页!$I$13+首页!$I$13,2) -> 0.35 | I34: armor_m8_alloys_energy_mod | J34: =ROUND((ROW()-ROW(J$27))*0.1*首页!$J$13+首页!$J$13,2) -> 1.73 | K34: damage_mod_reduction_m8 | L34: 0
A35: 9 | B35: 中型 | C35: shield_m9_alloys_upkeep_mod | D35: =ROUND((ROW()-ROW(D$27))*0.1*首页!$J$3+首页!$J$3,2) -> 0.41 | E35: shield_m9_alloys_energy_mod | F35: =ROUNDUP((ROW()-ROW(F$27))*0.1*首页!$K$3+首页!$K$3,2) -> 1.37 | G35: armor_m9_alloys_upkeep_mod | H35: =ROUND((ROW()-ROW(H$27))*0.1*首页!$I$13+首页!$I$13,2) -> 0.37 | I35: armor_m9_alloys_energy_mod | J35: =ROUND((ROW()-ROW(J$27))*0.1*首页!$J$13+首页!$J$13,2) -> 1.84 | K35: damage_mod_reduction_m9 | L35: 0
A36: 10 | B36: 中型 | C36: shield_m10_alloys_upkeep_mod | D36: =ROUND((ROW()-ROW(D$27))*0.1*首页!$J$3+首页!$J$3,2) -> 0.43 | E36: shield_m10_alloys_energy_mod | F36: =ROUNDUP((ROW()-ROW(F$27))*0.1*首页!$K$3+首页!$K$3,2) -> 1.45 | G36: armor_m10_alloys_upkeep_mod | H36: =ROUND((ROW()-ROW(H$27))*0.1*首页!$I$13+首页!$I$13,2) -> 0.39 | I36: armor_m10_alloys_energy_mod | J36: =ROUND((ROW()-ROW(J$27))*0.1*首页!$J$13+首页!$J$13,2) -> 1.94 | K36: damage_mod_reduction_m10 | L36: 0
A37: 11 | B37: 中型 | C37: shield_m11_alloys_upkeep_mod | D37: =ROUND((ROW()-ROW(D$27))*0.1*首页!$J$3+首页!$J$3,2) -> 0.46 | E37: shield_m11_alloys_energy_mod | F37: =ROUNDUP((ROW()-ROW(F$27))*0.1*首页!$K$3+首页!$K$3,2) -> 1.52 | G37: armor_m11_alloys_upkeep_mod | H37: =ROUND((ROW()-ROW(H$27))*0.1*首页!$I$13+首页!$I$13,2) -> 0.41 | I37: armor_m11_alloys_energy_mod | J37: =ROUND((ROW()-ROW(J$27))*0.1*首页!$J$13+首页!$J$13,2) -> 2.04 | K37: damage_mod_reduction_m11 | L37: 0
A38: 12 | B38: 中型 | C38: shield_m12_alloys_upkeep_mod | D38: =ROUND((ROW()-ROW(D$27))*0.1*首页!$J$3+首页!$J$3,2) -> 0.48 | E38: shield_m12_alloys_energy_mod | F38: =ROUNDUP((ROW()-ROW(F$27))*0.1*首页!$K$3+首页!$K$3,2) -> 1.6 | G38: armor_m12_alloys_upkeep_mod | H38: =ROUND((ROW()-ROW(H$27))*0.1*首页!$I$13+首页!$I$13,2) -> 0.43 | I38: armor_m12_alloys_energy_mod | J38: =ROUND((ROW()-ROW(J$27))*0.1*首页!$J$13+首页!$J$13,2) -> 2.14 | K38: damage_mod_reduction_m12 | L38: 0
A39: 13 | B39: 中型 | C39: shield_m13_alloys_upkeep_mod | D39: =ROUND((ROW()-ROW(D$27))*0.1*首页!$J$3+首页!$J$3,2) -> 0.5 | E39: shield_m13_alloys_energy_mod | F39: =ROUNDUP((ROW()-ROW(F$27))*0.1*首页!$K$3+首页!$K$3,2) -> 1.68 | G39: armor_m13_alloys_upkeep_mod | H39: =ROUND((ROW()-ROW(H$27))*0.1*首页!$I$13+首页!$I$13,2) -> 0.45 | I39: armor_m13_alloys_energy_mod | J39: =ROUND((ROW()-ROW(J$27))*0.1*首页!$J$13+首页!$J$13,2) -> 2.24 | K39: damage_mod_reduction_m13 | L39: 0
... A51: 25 | B51: 中型 | C51: shield_m25_alloys_upkeep_mod | D51: =ROUND((ROW()-ROW(D$27))*0.1*首页!$J$3+首页!$J$3,2) -> 0.78 | E51: shield_m25_alloys_energy_mod | F51: =ROUNDUP((ROW()-ROW(F$27))*0.1*首页!$K$3+首页!$K$3,2) -> 2.59 | G51: armor_m25_alloys_upkeep_mod | H51: =ROUND((ROW()-ROW(H$27))*0.1*首页!$I$13+首页!$I$13,2) -> 0.69 | I51: armor_m25_alloys_energy_mod | J51: =ROUND((ROW()-ROW(J$27))*0.1*首页!$J$13+首页!$J$13,2) -> 3.47 | K51: damage_mod_reduction_m25 | L51: 1
A53: 级别 | B53: 尺寸 | C53: 大型护盾组件能量维护费 | D53: 数值 | E53: 大型护盾组件能量维护费 | F53: 数值 | G53: 大型装甲合金维护费 | H53: 数值 | I53: 大型装甲能量维护费 | J53: 数值 | K53: 护盾船伤害减免 | L53: 数值
A54: 2 | B54: 大型 | C54: shield_l2_alloys_upkeep_mod | D54: =ROUND((ROW()-ROW(D$53))*0.1*首页!$J$4+首页!$J$4,2) -> 0.5 | E54: shield_l2_alloys_energy_mod | F54: =ROUNDUP((ROW()-ROW(F$53))*0.1*首页!$K$4+首页!$K$4,2) -> 1.68 | G54: armor_l2_alloys_upkeep_mod | H54: =ROUND((ROW()-ROW(H$53))*0.1*首页!$I$14+首页!$I$14,2) -> 0.45 | I54: armor_l2_alloys_energy_mod | J54: =ROUND((ROW()-ROW(J$53))*0.1*首页!$J$14+首页!$J$14,2) -> 2.23 | K54: damage_mod_reduction_l2 | L54: 0
A55: 3 | B55: 大型 | C55: shield_l3_alloys_upkeep_mod | D55: =ROUND((ROW()-ROW(D$53))*0.1*首页!$J$4+首页!$J$4,2) -> 0.55 | E55: shield_l3_alloys_energy_mod | F55: =ROUNDUP((ROW()-ROW(F$53))*0.1*首页!$K$4+首页!$K$4,2) -> 1.83 | G55: armor_l3_alloys_upkeep_mod | H55: =ROUND((ROW()-ROW(H$53))*0.1*首页!$I$14+首页!$I$14,2) -> 0.49 | I55: armor_l3_alloys_energy_mod | J55: =ROUND((ROW()-ROW(J$53))*0.1*首页!$J$14+首页!$J$14,2) -> 2.44 | K55: damage_mod_reduction_l3 | L55: 0
A56: 4 | B56: 大型 | C56: shield_l4_alloys_upkeep_mod | D56: =ROUND((ROW()-ROW(D$53))*0.1*首页!$J$4+首页!$J$4,2) -> 0.59 | E56: shield_l4_alloys_energy_mod | F56: =ROUNDUP((ROW()-ROW(F$53))*0.1*首页!$K$4+首页!$K$4,2) -> 1.98 | G56: armor_l4_alloys_upkeep_mod | H56: =ROUND((ROW()-ROW(H$53))*0.1*首页!$I$14+首页!$I$14,2) -> 0.53 | I56: armor_l4_alloys_energy_mod | J56: =ROUND((ROW()-ROW(J$53))*0.1*首页!$J$14+首页!$J$14,2) -> 2.64 | K56: damage_mod_reduction_l4 | L56: 0
A57: 5 | B57: 大型 | C57: shield_l5_alloys_upkeep_mod | D57: =ROUND((ROW()-ROW(D$53))*0.1*首页!$J$4+首页!$J$4,2) -> 0.64 | E57: shield_l5_alloys_energy_mod | F57: =ROUNDUP((ROW()-ROW(F$53))*0.1*首页!$K$4+首页!$K$4,2) -> 2.13 | G57: armor_l5_alloys_upkeep_mod | H57: =ROUND((ROW()-ROW(H$53))*0.1*首页!$I$14+首页!$I$14,2) -> 0.57 | I57: armor_l5_alloys_energy_mod | J57: =ROUND((ROW()-ROW(J$53))*0.1*首页!$J$14+首页!$J$14,2) -> 2.84 | K57: damage_mod_reduction_l5 | L57: 0
A58: 6 | B58: 大型 | C58: shield_l6_alloys_upkeep_mod | D58: =ROUND((ROW()-ROW(D$53))*0.1*首页!$J$4+首页!$J$4,2) -> 0.68 | E58: shield_l6_alloys_energy_mod | F58: =ROUNDUP((ROW()-ROW(F$53))*0.1*首页!$K$4+首页!$K$4,2) -> 2.28 | G58: armor_l6_alloys_upkeep_mod | H58: =ROUND((ROW()-ROW(H$53))*0.1*首页!$I$14+首页!$I$14,2) -> 0.61 | I58: armor_l6_alloys_energy_mod | J58: =ROUND((ROW()-ROW(J$53))*0.1*首页!$J$14+首页!$J$14,2) -> 3.05 | K58: damage_mod_reduction_l6 | L58: 0
A59: 7 | B59: 大型 | C59: shield_l7_alloys_upkeep_mod | D59: =ROUND((ROW()-ROW(D$53))*0.1*首页!$J$4+首页!$J$4,2) -> 0.73 | E59: shield_l7_alloys_energy_mod | F59: =ROUNDUP((ROW()-ROW(F$53))*0.1*首页!$K$4+首页!$K$4,2) -> 2.44 | G59: armor_l7_alloys_upkeep_mod | H59: =ROUND((ROW()-ROW(H$53))*0.1*首页!$I$14+首页!$I$14,2) -> 0.65 | I59: armor_l7_alloys_energy_mod | J59: =ROUND((ROW()-ROW(J$53))*0.1*首页!$J$14+首页!$J$14,2) -> 3.25 | K59: damage_mod_reduction_l7 | L59: 0
A60: 8 | B60: 大型 | C60: shield_l8_alloys_upkeep_mod | D60: =ROUND((ROW()-ROW(D$53))*0.1*首页!$J$4+首页!$J$4,2) -> 0.78 | E60: shield_l8_alloys_energy_mod | F60: =ROUNDUP((ROW()-ROW(F$53))*0.1*首页!$K$4+首页!$K$4,2) -> 2.59 | G60: armor_l8_alloys_upkeep_mod | H60: =ROUND((ROW()-ROW(H$53))*0.1*首页!$I$14+首页!$I$14,2) -> 0.69 | I60: armor_l8_alloys_energy_mod | J60: =ROUND((ROW()-ROW(J$53))*0.1*首页!$J$14+首页!$J$14,2) -> 3.45 | K60: damage_mod_reduction_l8 | L60: 0
A61: 9 | B61: 大型 | C61: shield_l9_alloys_upkeep_mod | D61: =ROUND((ROW()-ROW(D$53))*0.1*首页!$J$4+首页!$J$4,2) -> 0.82 | E61: shield_l9_alloys_energy_mod | F61: =ROUNDUP((ROW()-ROW(F$53))*0.1*首页!$K$4+首页!$K$4,2) -> 2.74 | G61: armor_l9_alloys_upkeep_mod | H61: =ROUND((ROW()-ROW(H$53))*0.1*首页!$I$14+首页!$I$14,2) -> 0.73 | I61: armor_l9_alloys_energy_mod | J61: =ROUND((ROW()-ROW(J$53))*0.1*首页!$J$14+首页!$J$14,2) -> 3.65 | K61: damage_mod_reduction_l9 | L61: 0
A62: 10 | B62: 大型 | C62: shield_l10_alloys_upkeep_mod | D62: =ROUND((ROW()-ROW(D$53))*0.1*首页!$J$4+首页!$J$4,2) -> 0.87 | E62: shield_l10_alloys_energy_mod | F62: =ROUNDUP((ROW()-ROW(F$53))*0.1*首页!$K$4+首页!$K$4,2) -> 2.89 | G62: armor_l10_alloys_upkeep_mod | H62: =ROUND((ROW()-ROW(H$53))*0.1*首页!$I$14+首页!$I$14,2) -> 0.77 | I62: armor_l10_alloys_energy_mod | J62: =ROUND((ROW()-ROW(J$53))*0.1*首页!$J$14+首页!$J$14,2) -> 3.86 | K62: damage_mod_reduction_l10 | L62: 0
A63: 11 | B63: 大型 | C63: shield_l11_alloys_upkeep_mod | D63: =ROUND((ROW()-ROW(D$53))*0.1*首页!$J$4+首页!$J$4,2) -> 0.91 | E63: shield_l11_alloys_energy_mod | F63: =ROUNDUP((ROW()-ROW(F$53))*0.1*首页!$K$4+首页!$K$4,2) -> 3.04 | G63: armor_l11_alloys_upkeep_mod | H63: =ROUND((ROW()-ROW(H$53))*0.1*首页!$I$14+首页!$I$14,2) -> 0.81 | I63: armor_l11_alloys_energy_mod | J63: =ROUND((ROW()-ROW(J$53))*0.1*首页!$J$14+首页!$J$14,2) -> 4.06 | K63: damage_mod_reduction_l11 | L63: 0
A64: 12 | B64: 大型 | C64: shield_l12_alloys_upkeep_mod | D64: =ROUND((ROW()-ROW(D$53))*0.1*首页!$J$4+首页!$J$4,2) -> 0.96 | E64: shield_l12_alloys_energy_mod | F64: =ROUNDUP((ROW()-ROW(F$53))*0.1*首页!$K$4+首页!$K$4,2) -> 3.2 | G64: armor_l12_alloys_upkeep_mod | H64: =ROUND((ROW()-ROW(H$53))*0.1*首页!$I$14+首页!$I$14,2) -> 0.85 | I64: armor_l12_alloys_energy_mod | J64: =ROUND((ROW()-ROW(J$53))*0.1*首页!$J$14+首页!$J$14,2) -> 4.26 | K64: damage_mod_reduction_l12 | L64: 0
...

Sheet 灵能盾
A1: 级别 | B1: 尺寸 | C1: 游戏key | D1: 护盾承受值 | E1: 数值 | F1: 合金花费 | G1: 数值 | H1: 泽洛花费 | I1: 数值 | J1: 护盾日回复值 | K1: 数值
A2: 2 | B2: 小型 | C2: SMALL_PSI_SHIELD_2 | D2: shield_mod_s2 | E2: =(ROW()-ROW(E$1)+1)*首页!$B$2 -> 800 | F2: shield_mod_s2_alloys_cost | G2: =(ROW()-ROW(G$1)+1)*首页!$F$2 -> 82 | H2: shield_mod_s2_zro_cost | I2: =ROUND((ROW()-ROW(I$1)+1)*首页!$G$2,2) -> 0.22 | J2: shield_mod_regen_s2 | K2: =ROUNDUP(E2/(首页!$D$2-MIN(LN(ROW()-ROW(K$1)+1)/LN(25)*(首页!$D$2-首页!$E$2),(首页!$D$2-首页!$E$2))),0) -> 5
A3: 3 | B3: 小型 | C3: SMALL_PSI_SHIELD_3 | D3: shield_mod_s3 | E3: =(ROW()-ROW(E$1)+1)*首页!$B$2 -> 1200 | F3: shield_mod_s3_alloys_cost | G3: =(ROW()-ROW(G$1)+1)*首页!$F$2 -> 123 | H3: shield_mod_s3_zro_cost | I3: =ROUND((ROW()-ROW(I$1)+1)*首页!$G$2,2) -> 0.33 | J3: shield_mod_regen_s3 | K3: =ROUNDUP(E3/(首页!$D$2-MIN(LN(ROW()-ROW(K$1)+1)/LN(25)*(首页!$D$2-首页!$E$2),(首页!$D$2-首页!$E$2))),0) -> 8
A4: 4 | B4: 小型 | C4: SMALL_PSI_SHIELD_4 | D4: shield_mod_s4 | E4: =(ROW()-ROW(E$1)+1)*首页!$B$2 -> 1600 | F4: shield_mod_s4_alloys_cost | G4: =(ROW()-ROW(G$1)+1)*首页!$F$2 -> 164 | H4: shield_mod_s4_zro_cost | I4: =ROUND((ROW()-ROW(I$1)+1)*首页!$G$2,2) -> 0.44 | J4: shield_mod_regen_s4 | K4: =ROUNDUP(E4/(首页!$D$2-MIN(LN(ROW()-ROW(K$1)+1)/LN(25)*(首页!$D$2-首页!$E$2),(首页!$D$2-首页!$E$2))),0) -> 11
A5: 5 | B5: 小型 | C5: SMALL_PSI_SHIELD_5 | D5: shield_mod_s5 | E5: =(ROW()-ROW(E$1)+1)*首页!$B$2 -> 2000 | F5: shield_mod_s5_alloys_cost | G5: =(ROW()-ROW(G$1)+1)*首页!$F$2 -> 205 | H5: shield_mod_s5_zro_cost | I5: =ROUND((ROW()-ROW(I$1)+1)*首页!$G$2,2) -> 0.55 | J5: shield_mod_regen_s5 | K5: =ROUNDUP(E5/(首页!$D$2-MIN(LN(ROW()-ROW(K$1)+1)/LN(25)*(首页!$D$2-首页!$E$2),(首页!$D$2-首页!$E$2))),0) -> 15
A6: 6 | B6: 小型 | C6: SMALL_PSI_SHIELD_6 | D6: shield_mod_s6 | E6: =(ROW()-ROW(E$1)+1)*首页!$B$2 -> 2400 | F6: shield_mod_s6_alloys_cost | G6: =(ROW()-ROW(G$1)+1)*首页!$F$2 -> 246 | H6: shield_mod_s6_zro_cost | I6: =ROUND((ROW()-ROW(I$1)+1)*首页!$G$2,2) -> 0.66 | J6: shield_mod_regen_s6 | K6: =ROUNDUP(E6/(首页!$D$2-MIN(LN(ROW()-ROW(K$1)+1)/LN(25)*(首页!$D$2-首页!$E$2),(首页!$D$2-首页!$E$2))),0) -> 19
A7: 7 | B7: 小型 | C7: SMALL_PSI_SHIELD_7 | D7: shield_mod_s7 | E7: =(ROW()-ROW(E$1)+1)*首页!$B$2 -> 2800 | F7: shield_mod_s7_alloys_cost | G7: =(ROW()-ROW(G$1)+1)*首页!$F$2 -> 287 | H7: shield_mod_s7_zro_cost | I7: =ROUND((ROW()-ROW(I$1)+1)*首页!$G$2,2) -> 0.77 | J7: shield_mod_regen_s7 | K7: =ROUNDUP(E7/(首页!$D$2-MIN(LN(ROW()-ROW(K$1)+1)/LN(25)*(首页!$D$2-首页!$E$2),(首页!$D$2-首页!$E$2))),0) -> 22
A8: 8 | B8: 小型 | C8: SMALL_PSI_SHIELD_8 | D8: shield_mod_s8 | E8: =(ROW()-ROW(E$1)+1)*首页!$B$2 -> 3200 | F8: shield_mod_s8_alloys_cost | G8: =(ROW()-ROW(G$1)+1)*首页!$F$2 -> 328 | H8: shield_mod_s8_zro_cost | I8: =ROUND((ROW()-ROW(I$1)+1)*首页!$G$2,2) -> 0.88 | J8: shield_mod_regen_s8 | K8: =ROUNDUP(E8/(首页!$D$2-MIN(LN(ROW()-ROW(K$1)+1)/LN(25)*(首页!$D$2-首页!$E$2),(首页!$D$2-首页!$E$2))),0) -> 27
A9: 9 | B9: 小型 | C9: SMALL_PSI_SHIELD_9 | D9: shield_mod_s9 | E9: =(ROW()-ROW(E$1)+1)*首页!$B$2 -> 3600 | F9: shield_mod_s9_alloys_cost | G9: =(ROW()-ROW(G$1)+1)*首页!$F$2 -> 369 | H9: shield_mod_s9_zro_cost | I9: =ROUND((ROW()-ROW(I$1)+1)*首页!$G$2,2) -> 0.99 | J9: shield_mod_regen_s9 | K9: =ROUNDUP(E9/(首页!$D$2-MIN(LN(ROW()-ROW(K$1)+1)/LN(25)*(首页!$D$2-首页!$E$2),(首页!$D$2-首页!$E$2))),0) -> 31
A10: 10 | B10: 小型 | C10: SMALL_PSI_SHIELD_10 | D10: shield_mod_s10 | E10: =(ROW()-ROW(E$1)+1)*首页!$B$2 -> 4000 | F10: shield_mod_s10_alloys_cost | G10: =(ROW()-ROW(G$1)+1)*首页!$F$2 -> 410 | H10: shield_mod_s10_zro_cost | I10: =ROUND((ROW()-ROW(I$1)+1)*首页!$G$2,2) -> 1.1 | J10: shield_mod_regen_s10 | K10: =ROUNDUP(E10/(首页!$D$2-MIN(LN(ROW()-ROW(K$1)+1)/LN(25)*(首页!$D$2-首页!$E$2),(首页!$D$2-首页!$E$2))),0) -> 36
A11: 11 | B11: 小型 | C11: SMALL_PSI_SHIELD_11 | D11: shield_mod_s11 | E11: =(ROW()-ROW(E$1)+1)*首页!$B$2 -> 4400 | F11: shield_mod_s11_alloys_cost | G11: =(ROW()-ROW(G$1)+1)*首页!$F$2 -> 451 | H11: shield_mod_s11_zro_cost | I11: =ROUND((ROW()-ROW(I$1)+1)*首页!$G$2,2) -> 1.21 | J11: shield_mod_regen_s11 | K11: =ROUNDUP(E11/(首页!$D$2-MIN(LN(ROW()-ROW(K$1)+1)/LN(25)*(首页!$D$2-首页!$E$2),(首页!$D$2-首页!$E$2))),0) -> 40
A12: 12 | B12: 小型 | C12: SMALL_PSI_SHIELD_12 | D12: shield_mod_s12 | E12: =(ROW()-ROW(E$1)+1)*首页!$B$2 -> 4800 | F12: shield_mod_s12_alloys_cost | G12: =(ROW()-ROW(G$1)+1)*首页!$F$2 -> 492 | H12: shield_mod_s12_zro_cost | I12: =ROUND((ROW()-ROW(I$1)+1)*首页!$G$2,2) -> 1.32 | J12: shield_mod_regen_s12 | K12: =ROUNDUP(E12/(首页!$D$2-MIN(LN(ROW()-ROW(K$1)+1)/LN(25)*(首页!$D$2-首页!$E$2),(首页!$D$2-首页!$E$2))),0) -> 45
A13: 13 | B13: 小型 | C13: SMALL_PSI_SHIELD_13 | D13: shield_mod_s13 | E13: =(ROW()-ROW(E$1)+1)*首页!$B$2 -> 5200 | F13: shield_mod_s13_alloys_cost | G13: =(ROW()-ROW(G$1)+1)*首页!$F$2 -> 533 | H13: shield_mod_s13_zro_cost | I13: =ROUND((ROW()-ROW(I$1)+1)*首页!$G$2,2) -> 1.43 | J13: shield_mod_regen_s13 | K13: =ROUNDUP(E13/(首页!$D$2-MIN(LN(ROW()-ROW(K$1)+1)/LN(25)*(首页!$D$2-首页!$E$2),(首页!$D$2-首页!$E$2))),0) -> 50
... A25: 25 | B25: 小型 | C25: SMALL_PSI_SHIELD_25 | D25: shield_mod_s25 | E25: =(ROW()-ROW(E$1)+1)*首页!$B$2 -> 10000 | F25: shield_mod_s25_alloys_cost | G25: =(ROW()-ROW(G$1)+1)*首页!$F$2 -> 1025 | H25: shield_mod_s25_zro_cost | I25: =ROUND((ROW()-ROW(I$1)+1)*首页!$G$2,2) -> 2.75 | J25: shield_mod_regen_s25 | K25: =ROUNDUP(E25/(首页!$D$2-MIN(LN(ROW()-ROW(K$1)+1)/LN(25)*(首页!$D$2-首页!$E$2),(首页!$D$2-首页!$E$2))),0) -> 125
A27: 级别 | B27: 尺寸 | C27: 游戏key | D27: 护盾承受值 | E27: 数值 | F27: 合金花费 | G27: 数值 | H27: 泽洛花费 | I27: 数值 | J27: 护盾日回复值 | K27: 数值
A28: 2 | B28: 中型 | C28: MEDIUM_PSI_SHIELD_2 | D28: shield_mod_m2 | E28: =(ROW()-ROW(E$27)+1)*首页!$B$3 -> 2400 | F28: shield_mod_m2_alloys_cost | G28: =(ROW()-ROW(E$27)+1)*首页!$F$3 -> 206 | H28: shield_mod_m2_zro_cost | I28: =ROUND((ROW()-ROW(I$27)+1)*首页!$G$3,2) -> 0.44 | J28: shield_mod_regen_m2 | K28: =ROUNDUP(E28/(首页!$D$3-MIN(LN(ROW()-ROW(K$27)+1)/LN(25)*(首页!$D$3-首页!$E$3),(首页!$D$3-首页!$E$3))),0) -> 14
A29: 3 | B29: 中型 | C29: MEDIUM_PSI_SHIELD_3 | D29: shield_mod_m3 | E29: =(ROW()-ROW(E$27)+1)*首页!$B$3 -> 3600 | F29: shield_mod_m3_alloys_cost | G29: =(ROW()-ROW(E$27)+1)*首页!$F$3 -> 309 | H29: shield_mod_m3_zro_cost | I29: =ROUND((ROW()-ROW(I$27)+1)*首页!$G$3,2) -> 0.66 | J29: shield_mod_regen_m3 | K29: =ROUNDUP(E29/(首页!$D$3-MIN(LN(ROW()-ROW(K$27)+1)/LN(25)*(首页!$D$3-首页!$E$3),(首页!$D$3-首页!$E$3))),0) -> 23
A30: 4 | B30: 中型 | C30: MEDIUM_PSI_SHIELD_4 | D30: shield_mod_m4 | E30: =(ROW()-ROW(E$27)+1)*首页!$B$3 -> 4800 | F30: shield_mod_m4_alloys_cost | G30: =(ROW()-ROW(E$27)+1)*首页!$F$3 -> 412 | H30: shield_mod_m4_zro_cost | I30: =ROUND((ROW()-ROW(I$27)+1)*首页!$G$3,2) -> 0.88 | J30: shield_mod_regen_m4 | K30: =ROUNDUP(E30/(首页!$D$3-MIN(LN(ROW()-ROW(K$27)+1)/LN(25)*(首页!$D$3-首页!$E$3),(首页!$D$3-首页!$E$3))),0) -> 33
A31: 5 | B31: 中型 | C31: MEDIUM_PSI_SHIELD_5 | D31: shield_mod_m5 | E31: =(ROW()-ROW(E$27)+1)*首页!$B$3 -> 6000 | F31: shield_mod_m5_alloys_cost | G31: =(ROW()-ROW(E$27)+1)*首页!$F$3 -> 515 | H31: shield_mod_m5_zro_cost | I31: =ROUND((ROW()-ROW(I$27)+1)*首页!$G$3,2) -> 1.1 | J31: shield_mod_regen_m5 | K31: =ROUNDUP(E31/(首页!$D$3-MIN(LN(ROW()-ROW(K$27)+1)/LN(25)*(首页!$D$3-首页!$E$3),(首页!$D$3-首页!$E$3))),0) -> 43
A32: 6 | B32: 中型 | C32: MEDIUM_PSI_SHIELD_6 | D32: shield_mod_m6 | E32: =(ROW()-ROW(E$27)+1)*首页!$B$3 -> 7200 | F32: shield_mod_m6_alloys_cost | G32: =(ROW()-ROW(E$27)+1)*首页!$F$3 -> 618 | H32: shield_mod_m6_zro_cost | I32: =ROUND((ROW()-ROW(I$27)+1)*首页!$G$3,2) -> 1.32 | J32: shield_mod_regen_m6 | K32: =ROUNDUP(E32/(首页!$D$3-MIN(LN(ROW()-ROW(K$27)+1)/LN(25)*(首页!$D$3-首页!$E$3),(首页!$D$3-首页!$E$3))),0) -> 55
A33: 7 | B33: 中型 | C33: MEDIUM_PSI_SHIELD_7 | D33: shield_mod_m7 | E33: =(ROW()-ROW(E$27)+1)*首页!$B$3 -> 8400 | F33: shield_mod_m7_alloys_cost | G33: =(ROW()-ROW(E$27)+1)*首页!$F$3 -> 721 | H33: shield_mod_m7_zro_cost | I33: =ROUND((ROW()-ROW(I$27)+1)*首页!$G$3,2) -> 1.54 | J33: shield_mod_regen_m7 | K33: =ROUNDUP(E33/(首页!$D$3-MIN(LN(ROW()-ROW(K$27)+1)/LN(25)*(首页!$D$3-首页!$E$3),(首页!$D$3-首页!$E$3))),0) -> 66
A34: 8 | B34: 中型 | C34: MEDIUM_PSI_SHIELD_8 | D34: shield_mod_m8 | E34: =(ROW()-ROW(E$27)+1)*首页!$B$3 -> 9600 | F34: shield_mod_m8_alloys_cost | G34: =(ROW()-ROW(E$27)+1)*首页!$F$3 -> 824 | H34: shield_mod_m8_zro_cost | I34: =ROUND((ROW()-ROW(I$27)+1)*首页!$G$3,2) -> 1.76 | J34: shield_mod_regen_m8 | K34: =ROUNDUP(E34/(首页!$D$3-MIN(LN(ROW()-ROW(K$27)+1)/LN(25)*(首页!$D$3-首页!$E$3),(首页!$D$3-首页!$E$3))),0) -> 79
A35: 9 | B35: 中型 | C35: MEDIUM_PSI_SHIELD_9 | D35: shield_mod_m9 | E35: =(ROW()-ROW(E$27)+1)*首页!$B$3 -> 10800 | F35: shield_mod_m9_alloys_cost | G35: =(ROW()-ROW(E$27)+1)*首页!$F$3 -> 927 | H35: shield_mod_m9_zro_cost | I35: =ROUND((ROW()-ROW(I$27)+1)*首页!$G$3,2) -> 1.98 | J35: shield_mod_regen_m9 | K35: =ROUNDUP(E35/(首页!$D$3-MIN(LN(ROW()-ROW(K$27)+1)/LN(25)*(首页!$D$3-首页!$E$3),(首页!$D$3-首页!$E$3))),0) -> 92
A36: 10 | B36: 中型 | C36: MEDIUM_PSI_SHIELD_10 | D36: shield_mod_m10 | E36: =(ROW()-ROW(E$27)+1)*首页!$B$3 -> 12000 | F36: shield_mod_m10_alloys_cost | G36: =(ROW()-ROW(E$27)+1)*首页!$F$3 -> 1030 | H36: shield_mod_m10_zro_cost | I36: =ROUND((ROW()-ROW(I$27)+1)*首页!$G$3,2) -> 2.2 | J36: shield_mod_regen_m10 | K36: =ROUNDUP(E36/(首页!$D$3-MIN(LN(ROW()-ROW(K$27)+1)/LN(25)*(首页!$D$3-首页!$E$3),(首页!$D$3-首页!$E$3))),0) -> 106
A37: 11 | B37: 中型 | C37: MEDIUM_PSI_SHIELD_11 | D37: shield_mod_m11 | E37: =(ROW()-ROW(E$27)+1)*首页!$B$3 -> 13200 | F37: shield_mod_m11_alloys_cost | G37: =(ROW()-ROW(E$27)+1)*首页!$F$3 -> 1133 | H37: shield_mod_m11_zro_cost | I37: =ROUND((ROW()-ROW(I$27)+1)*首页!$G$3,2) -> 2.42 | J37: shield_mod_regen_m11 | K37: =ROUNDUP(E37/(首页!$D$3-MIN(LN(ROW()-ROW(K$27)+1)/LN(25)*(首页!$D$3-首页!$E$3),(首页!$D$3-首页!$E$3))),0) -> 120
A38: 12 | B38: 中型 | C38: MEDIUM_PSI_SHIELD_12 | D38: shield_mod_m12 | E38: =(ROW()-ROW(E$27)+1)*首页!$B$3 -> 14400 | F38: shield_mod_m12_alloys_cost | G38: =(ROW()-ROW(E$27)+1)*首页!$F$3 -> 1236 | H38: shield_mod_m12_zro_cost | I38: =ROUND((ROW()-ROW(I$27)+1)*首页!$G$3,2) -> 2.64 | J38: shield_mod_regen_m12 | K38: =ROUNDUP(E38/(首页!$D$3-MIN(LN(ROW()-ROW(K$27)+1)/LN(25)*(首页!$D$3-首页!$E$3),(首页!$D$3-首页!$E$3))),0) -> 135
A39: 13 | B39: 中型 | C39: MEDIUM_PSI_SHIELD_13 | D39: shield_mod_m13 | E39: =(ROW()-ROW(E$27)+1)*首页!$B$3 -> 15600 | F39: shield_mod_m13_alloys_cost | G39: =(ROW()-ROW(E$27)+1)*首页!$F$3 -> 1339 | H39: shield_mod_m13_zro_cost | I39: =ROUND((ROW()-ROW(I$27)+1)*首页!$G$3,2) -> 2.86 | J39: shield_mod_regen_m13 | K39: =ROUNDUP(E39/(首页!$D$3-MIN(LN(ROW()-ROW(K$27)+1)/LN(25)*(首页!$D$3-首页!$E$3),(首页!$D$3-首页!$E$3))),0) -> 150
... A51: 25 | B51: 中型 | C51: MEDIUM_PSI_SHIELD_25 | D51: shield_mod_m25 | E51: =(ROW()-ROW(E$27)+1)*首页!$B$3 -> 30000 | F51: shield_mod_m25_alloys_cost | G51: =(ROW()-ROW(E$27)+1)*首页!$F$3 -> 2575 | H51: shield_mod_m25_zro_cost | I51: =ROUND((ROW()-ROW(I$27)+1)*首页!$G$3,2) -> 5.5 | J51: shield_mod_regen_m25 | K51: =ROUNDUP(E51/(首页!$D$3-MIN(LN(ROW()-ROW(K$27)+1)/LN(25)*(首页!$D$3-首页!$E$3),(首页!$D$3-首页!$E$3))),0) -> 375
A53: 级别 | B53: 尺寸 | C53: 游戏key | D53: 护盾承受值 | E53: 数值 | F53: 护盾合金花费 | G53: 数值 | H53: 护盾泽洛花费 | I53: 数值 | J53: 护盾日回复值 | K53: 数值
A54: 2 | B54: 大型 | C54: LARGE_PSI_SHIELD_2 | D54: shield_mod_l2 | E54: =(ROW()-ROW(E$53)+1)*首页!$B$4 -> 7200 | F54: shield_mod_l2_alloys_cost | G54: =(ROW()-ROW(G$53)+1)*首页!$F$4 -> 516 | H54: shield_mod_l2_zro_cost | I54: =ROUND((ROW()-ROW(I$53)+1)*首页!$G$4,2) -> 0.67 | J54: shield_mod_regen_l2 | K54: =ROUNDUP(E54/(首页!$D$4-MIN(LN((ROW()-ROW(K$53)+1))/LN(25)*(首页!$D$4-首页!$E$4),(首页!$D$4-首页!$E$4))),0) -> 42
A55: 3 | B55: 大型 | C55: LARGE_PSI_SHIELD_3 | D55: shield_mod_l3 | E55: =(ROW()-ROW(E$53)+1)*首页!$B$4 -> 10800 | F55: shield_mod_l3_alloys_cost | G55: =(ROW()-ROW(G$53)+1)*首页!$F$4 -> 774 | H55: shield_mod_l3_zro_cost | I55: =ROUND((ROW()-ROW(I$53)+1)*首页!$G$4,2) -> 1 | J55: shield_mod_regen_l3 | K55: =ROUNDUP(E55/(首页!$D$4-MIN(LN((ROW()-ROW(K$53)+1))/LN(25)*(首页!$D$4-首页!$E$4),(首页!$D$4-首页!$E$4))),0) -> 68
A56: 4 | B56: 大型 | C56: LARGE_PSI_SHIELD_4 | D56: shield_mod_l4 | E56: =(ROW()-ROW(E$53)+1)*首页!$B$4 -> 14400 | F56: shield_mod_l4_alloys_cost | G56: =(ROW()-ROW(G$53)+1)*首页!$F$4 -> 1032 | H56: shield_mod_l4_zro_cost | I56: =ROUND((ROW()-ROW(I$53)+1)*首页!$G$4,2) -> 1.33 | J56: shield_mod_regen_l4 | K56: =ROUNDUP(E56/(首页!$D$4-MIN(LN((ROW()-ROW(K$53)+1))/LN(25)*(首页!$D$4-首页!$E$4),(首页!$D$4-首页!$E$4))),0) -> 98
A57: 5 | B57: 大型 | C57: LARGE_PSI_SHIELD_5 | D57: shield_mod_l5 | E57: =(ROW()-ROW(E$53)+1)*首页!$B$4 -> 18000 | F57: shield_mod_l5_alloys_cost | G57: =(ROW()-ROW(G$53)+1)*首页!$F$4 -> 1290 | H57: shield_mod_l5_zro_cost | I57: =ROUND((ROW()-ROW(I$53)+1)*首页!$G$4,2) -> 1.67 | J57: shield_mod_regen_l5 | K57: =ROUNDUP(E57/(首页!$D$4-MIN(LN((ROW()-ROW(K$53)+1))/LN(25)*(首页!$D$4-首页!$E$4),(首页!$D$4-首页!$E$4))),0) -> 129
A58: 6 | B58: 大型 | C58: LARGE_PSI_SHIELD_6 | D58: shield_mod_l6 | E58: =(ROW()-ROW(E$53)+1)*首页!$B$4 -> 21600 | F58: shield_mod_l6_alloys_cost | G58: =(ROW()-ROW(G$53)+1)*首页!$F$4 -> 1548 | H58: shield_mod_l6_zro_cost | I58: =ROUND((ROW()-ROW(I$53)+1)*首页!$G$4,2) -> 2 | J58: shield_mod_regen_l6 | K58: =ROUNDUP(E58/(首页!$D$4-MIN(LN((ROW()-ROW(K$53)+1))/LN(25)*(首页!$D$4-首页!$E$4),(首页!$D$4-首页!$E$4))),0) -> 163
A59: 7 | B59: 大型 | C59: LARGE_PSI_SHIELD_7 | D59: shield_mod_l7 | E59: =(ROW()-ROW(E$53)+1)*首页!$B$4 -> 25200 | F59: shield_mod_l7_alloys_cost | G59: =(ROW()-ROW(G$53)+1)*首页!$F$4 -> 1806 | H59: shield_mod_l7_zro_cost | I59: =ROUND((ROW()-ROW(I$53)+1)*首页!$G$4,2) -> 2.33 | J59: shield_mod_regen_l7 | K59: =ROUNDUP(E59/(首页!$D$4-MIN(LN((ROW()-ROW(K$53)+1))/LN(25)*(首页!$D$4-首页!$E$4),(首页!$D$4-首页!$E$4))),0) -> 198
A60: 8 | B60: 大型 | C60: LARGE_PSI_SHIELD_8 | D60: shield_mod_l8 | E60: =(ROW()-ROW(E$53)+1)*首页!$B$4 -> 28800 | F60: shield_mod_l8_alloys_cost | G60: =(ROW()-ROW(G$53)+1)*首页!$F$4 -> 2064 | H60: shield_mod_l8_zro_cost | I60: =ROUND((ROW()-ROW(I$53)+1)*首页!$G$4,2) -> 2.66 | J60: shield_mod_regen_l8 | K60: =ROUNDUP(E60/(首页!$D$4-MIN(LN((ROW()-ROW(K$53)+1))/LN(25)*(首页!$D$4-首页!$E$4),(首页!$D$4-首页!$E$4))),0) -> 236
A61: 9 | B61: 大型 | C61: LARGE_PSI_SHIELD_9 | D61: shield_mod_l9 | E61: =(ROW()-ROW(E$53)+1)*首页!$B$4 -> 32400 | F61: shield_mod_l9_alloys_cost | G61: =(ROW()-ROW(G$53)+1)*首页!$F$4 -> 2322 | H61: shield_mod_l9_zro_cost | I61: =ROUND((ROW()-ROW(I$53)+1)*首页!$G$4,2) -> 3 | J61: shield_mod_regen_l9 | K61: =ROUNDUP(E61/(首页!$D$4-MIN(LN((ROW()-ROW(K$53)+1))/LN(25)*(首页!$D$4-首页!$E$4),(首页!$D$4-首页!$E$4))),0) -> 275
A62: 10 | B62: 大型 | C62: LARGE_PSI_SHIELD_10 | D62: shield_mod_l10 | E62: =(ROW()-ROW(E$53)+1)*首页!$B$4 -> 36000 | F62: shield_mod_l10_alloys_cost | G62: =(ROW()-ROW(G$53)+1)*首页!$F$4 -> 2580 | H62: shield_mod_l10_zro_cost | I62: =ROUND((ROW()-ROW(I$53)+1)*首页!$G$4,2) -> 3.33 | J62: shield_mod_regen_l10 | K62: =ROUNDUP(E62/(首页!$D$4-MIN(LN((ROW()-ROW(K$53)+1))/LN(25)*(首页!$D$4-首页!$E$4),(首页!$D$4-首页!$E$4))),0) -> 316
A63: 11 | B63: 大型 | C63: LARGE_PSI_SHIELD_11 | D63: shield_mod_l11 | E63: =(ROW()-ROW(E$53)+1)*首页!$B$4 -> 39600 | F63: shield_mod_l11_alloys_cost | G63: =(ROW()-ROW(G$53)+1)*首页!$F$4 -> 2838 | H63: shield_mod_l11_zro_cost | I63: =ROUND((ROW()-ROW(I$53)+1)*首页!$G$4,2) -> 3.66 | J63: shield_mod_regen_l11 | K63: =ROUNDUP(E63/(首页!$D$4-MIN(LN((ROW()-ROW(K$53)+1))/LN(25)*(首页!$D$4-首页!$E$4),(首页!$D$4-首页!$E$4))),0) -> 359
A64: 12 | B64: 大型 | C64: LARGE_PSI_SHIELD_12 | D64: shield_mod_l12 | E64: =(ROW()-ROW(E$53)+1)*首页!$B$4 -> 43200 | F64: shield_mod_l12_alloys_cost | G64: =(ROW()-ROW(G$53)+1)*首页!$F$4 -> 3096 | H64: shield_mod_l12_zro_cost | I64: =ROUND((ROW()-ROW(I$53)+1)*首页!$G$4,2) -> 4 | J64: shield_mod_regen_l12 | K64: =ROUNDUP(E64/(首页!$D$4-MIN(LN((ROW()-ROW(K$53)+1))/LN(25)*(首页!$D$4-首页!$E$4),(首页!$D$4-首页!$E$4))),0) -> 403
...

Sheet 泽珞护盾肌体
A1: 级别 | B1: 尺寸 | C1: 游戏key | D1: 护盾承受值 | E1: 数值 | F1: 护盾日回复值 | G1: 数值
A2: 2 | B2: 小型 | C2: SMALL_PSI_BIO_SHIELD_2 | D2: app_bio_shield_s2 | E2: =(ROW()-ROW(E$1)+1)*首页!$B$5 -> 640 | F2: app_bio_shield_regen_s2 | G2: =ROUNDUP(E2/首页!$E$5,0) -> 8
A3: 3 | B3: 小型 | C3: SMALL_PSI_BIO_SHIELD_3 | D3: app_bio_shield_s3 | E3: =(ROW()-ROW(E$1)+1)*首页!$B$5 -> 960 | F3: app_bio_shield_regen_s3 | G3: =ROUNDUP(E3/首页!$E$5,0) -> 12
A4: 4 | B4: 小型 | C4: SMALL_PSI_BIO_SHIELD_4 | D4: app_bio_shield_s4 | E4: =(ROW()-ROW(E$1)+1)*首页!$B$5 -> 1280 | F4: app_bio_shield_regen_s4 | G4: =ROUNDUP(E4/首页!$E$5,0) -> 16
A5: 5 | B5: 小型 | C5: SMALL_PSI_BIO_SHIELD_5 | D5: app_bio_shield_s5 | E5: =(ROW()-ROW(E$1)+1)*首页!$B$5 -> 1600 | F5: app_bio_shield_regen_s5 | G5: =ROUNDUP(E5/首页!$E$5,0) -> 20
A6: 6 | B6: 小型 | C6: SMALL_PSI_BIO_SHIELD_6 | D6: app_bio_shield_s6 | E6: =(ROW()-ROW(E$1)+1)*首页!$B$5 -> 1920 | F6: app_bio_shield_regen_s6 | G6: =ROUNDUP(E6/首页!$E$5,0) -> 24
A7: 7 | B7: 小型 | C7: SMALL_PSI_BIO_SHIELD_7 | D7: app_bio_shield_s7 | E7: =(ROW()-ROW(E$1)+1)*首页!$B$5 -> 2240 | F7: app_bio_shield_regen_s7 | G7: =ROUNDUP(E7/首页!$E$5,0) -> 28
A8: 8 | B8: 小型 | C8: SMALL_PSI_BIO_SHIELD_8 | D8: app_bio_shield_s8 | E8: =(ROW()-ROW(E$1)+1)*首页!$B$5 -> 2560 | F8: app_bio_shield_regen_s8 | G8: =ROUNDUP(E8/首页!$E$5,0) -> 32
A9: 9 | B9: 小型 | C9: SMALL_PSI_BIO_SHIELD_9 | D9: app_bio_shield_s9 | E9: =(ROW()-ROW(E$1)+1)*首页!$B$5 -> 2880 | F9: app_bio_shield_regen_s9 | G9: =ROUNDUP(E9/首页!$E$5,0) -> 36
A10: 10 | B10: 小型 | C10: SMALL_PSI_BIO_SHIELD_10 | D10: app_bio_shield_s10 | E10: =(ROW()-ROW(E$1)+1)*首页!$B$5 -> 3200 | F10: app_bio_shield_regen_s10 | G10: =ROUNDUP(E10/首页!$E$5,0) -> 40
A11: 11 | B11: 小型 | C11: SMALL_PSI_BIO_SHIELD_11 | D11: app_bio_shield_s11 | E11: =(ROW()-ROW(E$1)+1)*首页!$B$5 -> 3520 | F11: app_bio_shield_regen_s11 | G11: =ROUNDUP(E11/首页!$E$5,0) -> 44
A12: 12 | B12: 小型 | C12: SMALL_PSI_BIO_SHIELD_12 | D12: app_bio_shield_s12 | E12: =(ROW()-ROW(E$1)+1)*首页!$B$5 -> 3840 | F12: app_bio_shield_regen_s12 | G12: =ROUNDUP(E12/首页!$E$5,0) -> 48
A13: 13 | B13: 小型 | C13: SMALL_PSI_BIO_SHIELD_13 | D13: app_bio_shield_s13 | E13: =(ROW()-ROW(E$1)+1)*首页!$B$5 -> 4160 | F13: app_bio_shield_regen_s13 | G13: =ROUNDUP(E13/首页!$E$5,0) -> 52
... A25: 25 | B25: 小型 | C25: SMALL_PSI_BIO_SHIELD_25 | D25: app_bio_shield_s25 | E25: =(ROW()-ROW(E$1)+1)*首页!$B$5 -> 8000 | F25: app_bio_shield_regen_s25 | G25: =ROUNDUP(E25/首页!$E$5,0) -> 100
A27: 级别 | B27: 尺寸 | C27: 游戏key | D27: 护盾承受值 | E27: 数值 | F27: 护盾日回复值 | G27: 数值
A28: 2 | B28: 中型 | C28: MEDIUM_PSI_BIO_SHIELD_2 | D28: app_bio_shield_m2 | E28: =(ROW()-ROW(E$27)+1)*首页!$B$6 -> 1920 | F28: app_bio_shield_regen_m2 | G28: =E28/首页!$E$6 -> 24
A29: 3 | B29: 中型 | C29: MEDIUM_PSI_BIO_SHIELD_3 | D29: app_bio_shield_m3 | E29: =(ROW()-ROW(E$27)+1)*首页!$B$6 -> 2880 | F29: app_bio_shield_regen_m3 | G29: =E29/首页!$E$6 -> 36
A30: 4 | B30: 中型 | C30: MEDIUM_PSI_BIO_SHIELD_4 | D30: app_bio_shield_m4 | E30: =(ROW()-ROW(E$27)+1)*首页!$B$6 -> 3840 | F30: app_bio_shield_regen_m4 | G30: =E30/首页!$E$6 -> 48
A31: 5 | B31: 中型 | C31: MEDIUM_PSI_BIO_SHIELD_5 | D31: app_bio_shield_m5 | E31: =(ROW()-ROW(E$27)+1)*首页!$B$6 -> 4800 | F31: app_bio_shield_regen_m5 | G31: =E31/首页!$E$6 -> 60
A32: 6 | B32: 中型 | C32: MEDIUM_PSI_BIO_SHIELD_6 | D32: app_bio_shield_m6 | E32: =(ROW()-ROW(E$27)+1)*首页!$B$6 -> 5760 | F32: app_bio_shield_regen_m6 | G32: =E32/首页!$E$6 -> 72
A33: 7 | B33: 中型 | C33: MEDIUM_PSI_BIO_SHIELD_7 | D33: app_bio_shield_m7 | E33: =(ROW()-ROW(E$27)+1)*首页!$B$6 -> 6720 | F33: app_bio_shield_regen_m7 | G33: =E33/首页!$E$6 -> 84
A34: 8 | B34: 中型 | C34: MEDIUM_PSI_BIO_SHIELD_8 | D34: app_bio_shield_m8 | E34: =(ROW()-ROW(E$27)+1)*首页!$B$6 -> 7680 | F34: app_bio_shield_regen_m8 | G34: =E34/首页!$E$6 -> 96
A35: 9 | B35: 中型 | C35: MEDIUM_PSI_BIO_SHIELD_9 | D35: app_bio_shield_m9 | E35: =(ROW()-ROW(E$27)+1)*首页!$B$6 -> 8640 | F35: app_bio_shield_regen_m9 | G35: =E35/首页!$E$6 -> 108
A36: 10 | B36: 中型 | C36: MEDIUM_PSI_BIO_SHIELD_10 | D36: app_bio_shield_m10 | E36: =(ROW()-ROW(E$27)+1)*首页!$B$6 -> 9600 | F36: app_bio_shield_regen_m10 | G36: =E36/首页!$E$6 -> 120
A37: 11 | B37: 中型 | C37: MEDIUM_PSI_BIO_SHIELD_11 | D37: app_bio_shield_m11 | E37: =(ROW()-ROW(E$27)+1)*首页!$B$6 -> 10560 | F37: app_bio_shield_regen_m11 | G37: =E37/首页!$E$6 -> 132
A38: 12 | B38: 中型 | C38: MEDIUM_PSI_BIO_SHIELD_12 | D38: app_bio_shield_m12 | E38: =(ROW()-ROW(E$27)+1)*首页!$B$6 -> 11520 | F38: app_bio_shield_regen_m12 | G38: =E38/首页!$E$6 -> 144
A39: 13 | B39: 中型 | C39: MEDIUM_PSI_BIO_SHIELD_13 | D39: app_bio_shield_m13 | E39: =(ROW()-ROW(E$27)+1)*首页!$B$6 -> 12480 | F39: app_bio_shield_regen_m13 | G39: =E39/首页!$E$6 -> 156
... A51: 25 | B51: 中型 | C51: MEDIUM_PSI_BIO_SHIELD_25 | D51: app_bio_shield_m25 | E51: =(ROW()-ROW(E$27)+1)*首页!$B$6 -> 24000 | F51: app_bio_shield_regen_m25 | G51: =E51/首页!$E$6 -> 300
A53: 级别 | B53: 尺寸 | C53: 游戏key | D53: 护盾承受值 | E53: 数值 | F53: 护盾日回复值 | G53: 数值
A54: 2 | B54: 大型 | C54: LARGE_PSI_BIO_SHIELD_2 | D54: app_bio_shield_l2 | E54: =(ROW()-ROW(E$53)+1)*首页!$B$7 -> 5760 | F54: app_bio_shield_regen_l2 | G54: =E54/首页!$E$7 -> 72
A55: 3 | B55: 大型 | C55: LARGE_PSI_BIO_SHIELD_3 | D55: app_bio_shield_l3 | E55: =(ROW()-ROW(E$53)+1)*首页!$B$7 -> 8640 | F55: app_bio_shield_regen_l3 | G55: =E55/首页!$E$7 -> 108
A56: 4 | B56: 大型 | C56: LARGE_PSI_BIO_SHIELD_4 | D56: app_bio_shield_l4 | E56: =(ROW()-ROW(E$53)+1)*首页!$B$7 -> 11520 | F56: app_bio_shield_regen_l4 | G56: =E56/首页!$E$7 -> 144
A57: 5 | B57: 大型 | C57: LARGE_PSI_BIO_SHIELD_5 | D57: app_bio_shield_l5 | E57: =(ROW()-ROW(E$53)+1)*首页!$B$7 -> 14400 | F57: app_bio_shield_regen_l5 | G57: =E57/首页!$E$7 -> 180
A58: 6 | B58: 大型 | C58: LARGE_PSI_BIO_SHIELD_6 | D58: app_bio_shield_l6 | E58: =(ROW()-ROW(E$53)+1)*首页!$B$7 -> 17280 | F58: app_bio_shield_regen_l6 | G58: =E58/首页!$E$7 -> 216
A59: 7 | B59: 大型 | C59: LARGE_PSI_BIO_SHIELD_7 | D59: app_bio_shield_l7 | E59: =(ROW()-ROW(E$53)+1)*首页!$B$7 -> 20160 | F59: app_bio_shield_regen_l7 | G59: =E59/首页!$E$7 -> 252
A60: 8 | B60: 大型 | C60: LARGE_PSI_BIO_SHIELD_8 | D60: app_bio_shield_l8 | E60: =(ROW()-ROW(E$53)+1)*首页!$B$7 -> 23040 | F60: app_bio_shield_regen_l8 | G60: =E60/首页!$E$7 -> 288
A61: 9 | B61: 大型 | C61: LARGE_PSI_BIO_SHIELD_9 | D61: app_bio_shield_l9 | E61: =(ROW()-ROW(E$53)+1)*首页!$B$7 -> 25920 | F61: app_bio_shield_regen_l9 | G61: =E61/首页!$E$7 -> 324
A62: 10 | B62: 大型 | C62: LARGE_PSI_BIO_SHIELD_10 | D62: app_bio_shield_l10 | E62: =(ROW()-ROW(E$53)+1)*首页!$B$7 -> 28800 | F62: app_bio_shield_regen_l10 | G62: =E62/首页!$E$7 -> 360
A63: 11 | B63: 大型 | C63: LARGE_PSI_BIO_SHIELD_11 | D63: app_bio_shield_l11 | E63: =(ROW()-ROW(E$53)+1)*首页!$B$7 -> 31680 | F63: app_bio_shield_regen_l11 | G63: =E63/首页!$E$7 -> 396
A64: 12 | B64: 大型 | C64: LARGE_PSI_BIO_SHIELD_12 | D64: app_bio_shield_l12 | E64: =(ROW()-ROW(E$53)+1)*首页!$B$7 -> 34560 | F64: app_bio_shield_regen_l12 | G64: =E64/首页!$E$7 -> 432
...

Sheet 古代脉冲甲
A1: 级别 | B1: 尺寸 | C1: 游戏key | D1: 基础护盾承受值 | E1: 数值 | F1: 护盾承受值加成 | G1: 数值 | H1: 总护盾值 | I1: 护盾每日回复 | J1: 数值 | K1: 装甲值 | L1: 数值 | M1: 合金花费 | N1: 数值 | O1: 稀有文物花费
A2: 2 | B2: 小型 | C2: SMALL_ARCHAEO_ARMOR_2 | D2: archaeo_shield_s2 | E2: =(ROW()-ROW(E$1)+1)*首页!$B$12 -> 200 | F2: archaeo_shield_s2_buff | G2: =(ROW()-ROW(G$1)+1)*首页!$C$12 -> 200 | H2: =E2+G2 -> 400 | I2: archaeo_shield_regen_s2 | J2: =ROUNDUP(H2/首页!$E$12,0) -> 2 | K2: archaeo_armor_s2 | L2: =(ROW()-ROW(L$1)+1)*首页!$F$12 -> 320 | M2: archaeo_alloys_cost_s2 | N2: =ROUNDUP((ROW()-ROW(N$1)+1)*首页!$L$12*首页!$H$12,0) -> 35 | O2: =首页!$K$12 -> 8
A3: 3 | B3: 小型 | C3: SMALL_ARCHAEO_ARMOR_3 | D3: archaeo_shield_s3 | E3: =(ROW()-ROW(E$1)+1)*首页!$B$12 -> 300 | F3: archaeo_shield_s3_buff | G3: =(ROW()-ROW(G$1)+1)*首页!$C$12 -> 300 | H3: =E3+G3 -> 600 | I3: archaeo_shield_regen_s3 | J3: =ROUNDUP(H3/首页!$E$12,0) -> 3 | K3: archaeo_armor_s3 | L3: =(ROW()-ROW(L$1)+1)*首页!$F$12 -> 480 | M3: archaeo_alloys_cost_s3 | N3: =ROUNDUP((ROW()-ROW(N$1)+1)*首页!$L$12*首页!$H$12,0) -> 53 | O3: =首页!$K$12 -> 8
A4: 4 | B4: 小型 | C4: SMALL_ARCHAEO_ARMOR_4 | D4: archaeo_shield_s4 | E4: =(ROW()-ROW(E$1)+1)*首页!$B$12 -> 400 | F4: archaeo_shield_s4_buff | G4: =(ROW()-ROW(G$1)+1)*首页!$C$12 -> 400 | H4: =E4+G4 -> 800 | I4: archaeo_shield_regen_s4 | J4: =ROUNDUP(H4/首页!$E$12,0) -> 4 | K4: archaeo_armor_s4 | L4: =(ROW()-ROW(L$1)+1)*首页!$F$12 -> 640 | M4: archaeo_alloys_cost_s4 | N4: =ROUNDUP((ROW()-ROW(N$1)+1)*首页!$L$12*首页!$H$12,0) -> 70 | O4: =首页!$K$12 -> 8
A5: 5 | B5: 小型 | C5: SMALL_ARCHAEO_ARMOR_5 | D5: archaeo_shield_s5 | E5: =(ROW()-ROW(E$1)+1)*首页!$B$12 -> 500 | F5: archaeo_shield_s5_buff | G5: =(ROW()-ROW(G$1)+1)*首页!$C$12 -> 500 | H5: =E5+G5 -> 1000 | I5: archaeo_shield_regen_s5 | J5: =ROUNDUP(H5/首页!$E$12,0) -> 5 | K5: archaeo_armor_s5 | L5: =(ROW()-ROW(L$1)+1)*首页!$F$12 -> 800 | M5: archaeo_alloys_cost_s5 | N5: =ROUNDUP((ROW()-ROW(N$1)+1)*首页!$L$12*首页!$H$12,0) -> 88 | O5: =首页!$K$12 -> 8
A6: 6 | B6: 小型 | C6: SMALL_ARCHAEO_ARMOR_6 | D6: archaeo_shield_s6 | E6: =(ROW()-ROW(E$1)+1)*首页!$B$12 -> 600 | F6: archaeo_shield_s6_buff | G6: =(ROW()-ROW(G$1)+1)*首页!$C$12 -> 600 | H6: =E6+G6 -> 1200 | I6: archaeo_shield_regen_s6 | J6: =ROUNDUP(H6/首页!$E$12,0) -> 6 | K6: archaeo_armor_s6 | L6: =(ROW()-ROW(L$1)+1)*首页!$F$12 -> 960 | M6: archaeo_alloys_cost_s6 | N6: =ROUNDUP((ROW()-ROW(N$1)+1)*首页!$L$12*首页!$H$12,0) -> 105 | O6: =首页!$K$12 -> 8
A7: 7 | B7: 小型 | C7: SMALL_ARCHAEO_ARMOR_7 | D7: archaeo_shield_s7 | E7: =(ROW()-ROW(E$1)+1)*首页!$B$12 -> 700 | F7: archaeo_shield_s7_buff | G7: =(ROW()-ROW(G$1)+1)*首页!$C$12 -> 700 | H7: =E7+G7 -> 1400 | I7: archaeo_shield_regen_s7 | J7: =ROUNDUP(H7/首页!$E$12,0) -> 7 | K7: archaeo_armor_s7 | L7: =(ROW()-ROW(L$1)+1)*首页!$F$12 -> 1120 | M7: archaeo_alloys_cost_s7 | N7: =ROUNDUP((ROW()-ROW(N$1)+1)*首页!$L$12*首页!$H$12,0) -> 123 | O7: =首页!$K$12 -> 8
A8: 8 | B8: 小型 | C8: SMALL_ARCHAEO_ARMOR_8 | D8: archaeo_shield_s8 | E8: =(ROW()-ROW(E$1)+1)*首页!$B$12 -> 800 | F8: archaeo_shield_s8_buff | G8: =(ROW()-ROW(G$1)+1)*首页!$C$12 -> 800 | H8: =E8+G8 -> 1600 | I8: archaeo_shield_regen_s8 | J8: =ROUNDUP(H8/首页!$E$12,0) -> 8 | K8: archaeo_armor_s8 | L8: =(ROW()-ROW(L$1)+1)*首页!$F$12 -> 1280 | M8: archaeo_alloys_cost_s8 | N8: =ROUNDUP((ROW()-ROW(N$1)+1)*首页!$L$12*首页!$H$12,0) -> 140 | O8: =首页!$K$12 -> 8
A9: 9 | B9: 小型 | C9: SMALL_ARCHAEO_ARMOR_9 | D9: archaeo_shield_s9 | E9: =(ROW()-ROW(E$1)+1)*首页!$B$12 -> 900 | F9: archaeo_shield_s9_buff | G9: =(ROW()-ROW(G$1)+1)*首页!$C$12 -> 900 | H9: =E9+G9 -> 1800 | I9: archaeo_shield_regen_s9 | J9: =ROUNDUP(H9/首页!$E$12,0) -> 9 | K9: archaeo_armor_s9 | L9: =(ROW()-ROW(L$1)+1)*首页!$F$12 -> 1440 | M9: archaeo_alloys_cost_s9 | N9: =ROUNDUP((ROW()-ROW(N$1)+1)*首页!$L$12*首页!$H$12,0) -> 158 | O9: =首页!$K$12 -> 8
A10: 10 | B10: 小型 | C10: SMALL_ARCHAEO_ARMOR_10 | D10: archaeo_shield_s10 | E10: =(ROW()-ROW(E$1)+1)*首页!$B$12 -> 1000 | F10: archaeo_shield_s10_buff | G10: =(ROW()-ROW(G$1)+1)*首页!$C$12 -> 1000 | H10: =E10+G10 -> 2000 | I10: archaeo_shield_regen_s10 | J10: =ROUNDUP(H10/首页!$E$12,0) -> 10 | K10: archaeo_armor_s10 | L10: =(ROW()-ROW(L$1)+1)*首页!$F$12 -> 1600 | M10: archaeo_alloys_cost_s10 | N10: =ROUNDUP((ROW()-ROW(N$1)+1)*首页!$L$12*首页!$H$12,0) -> 175 | O10: =首页!$K$12 -> 8
A11: 11 | B11: 小型 | C11: SMALL_ARCHAEO_ARMOR_11 | D11: archaeo_shield_s11 | E11: =(ROW()-ROW(E$1)+1)*首页!$B$12 -> 1100 | F11: archaeo_shield_s11_buff | G11: =(ROW()-ROW(G$1)+1)*首页!$C$12 -> 1100 | H11: =E11+G11 -> 2200 | I11: archaeo_shield_regen_s11 | J11: =ROUNDUP(H11/首页!$E$12,0) -> 11 | K11: archaeo_armor_s11 | L11: =(ROW()-ROW(L$1)+1)*首页!$F$12 -> 1760 | M11: archaeo_alloys_cost_s11 | N11: =ROUNDUP((ROW()-ROW(N$1)+1)*首页!$L$12*首页!$H$12,0) -> 193 | O11: =首页!$K$12 -> 8
A12: 12 | B12: 小型 | C12: SMALL_ARCHAEO_ARMOR_12 | D12: archaeo_shield_s12 | E12: =(ROW()-ROW(E$1)+1)*首页!$B$12 -> 1200 | F12: archaeo_shield_s12_buff | G12: =(ROW()-ROW(G$1)+1)*首页!$C$12 -> 1200 | H12: =E12+G12 -> 2400 | I12: archaeo_shield_regen_s12 | J12: =ROUNDUP(H12/首页!$E$12,0) -> 12 | K12: archaeo_armor_s12 | L12: =(ROW()-ROW(L$1)+1)*首页!$F$12 -> 1920 | M12: archaeo_alloys_cost_s12 | N12: =ROUNDUP((ROW()-ROW(N$1)+1)*首页!$L$12*首页!$H$12,0) -> 210 | O12: =首页!$K$12 -> 8
A13: 13 | B13: 小型 | C13: SMALL_ARCHAEO_ARMOR_13 | D13: archaeo_shield_s13 | E13: =(ROW()-ROW(E$1)+1)*首页!$B$12 -> 1300 | F13: archaeo_shield_s13_buff | G13: =(ROW()-ROW(G$1)+1)*首页!$C$12 -> 1300 | H13: =E13+G13 -> 2600 | I13: archaeo_shield_regen_s13 | J13: =ROUNDUP(H13/首页!$E$12,0) -> 13 | K13: archaeo_armor_s13 | L13: =(ROW()-ROW(L$1)+1)*首页!$F$12 -> 2080 | M13: archaeo_alloys_cost_s13 | N13: =ROUNDUP((ROW()-ROW(N$1)+1)*首页!$L$12*首页!$H$12,0) -> 228 | O13: =首页!$K$12 -> 8
... A25: 25 | B25: 小型 | C25: SMALL_ARCHAEO_ARMOR_25 | D25: archaeo_shield_s25 | E25: =(ROW()-ROW(E$1)+1)*首页!$B$12 -> 2500 | F25: archaeo_shield_s25_buff | G25: =(ROW()-ROW(G$1)+1)*首页!$C$12 -> 2500 | H25: =E25+G25 -> 5000 | I25: archaeo_shield_regen_s25 | J25: =ROUNDUP(H25/首页!$E$12,0) -> 25 | K25: archaeo_armor_s25 | L25: =(ROW()-ROW(L$1)+1)*首页!$F$12 -> 4000 | M25: archaeo_alloys_cost_s25 | N25: =ROUNDUP((ROW()-ROW(N$1)+1)*首页!$L$12*首页!$H$12,0) -> 438 | O25: =首页!$K$12 -> 8
A27: 级别 | B27: 尺寸 | C27: 游戏key | D27: 基础护盾承受值 | E27: 数值 | F27: 护盾承受值加成 | G27: 数值 | H27: 护盾承受值 | I27: 护盾每日回复 | J27: 数值 | K27: 装甲值 | L27: 数值 | M27: 合金花费 | N27: 数值 | O27: 稀有文物花费
A28: 2 | B28: 中型 | C28: MEDIUM_ARCHAEO_ARMOR_2 | D28: archaeo_shield_m2 | E28: =(ROW()-ROW(E$27)+1)*首页!$B$13 -> 600 | F28: archaeo_shield_m2_buff | G28: =(ROW()-ROW(G$27)+1)*首页!$C$13 -> 600 | H28: =E28+G28 -> 1200 | I28: archaeo_shield_regen_m2 | J28: =ROUNDUP(H28/首页!E13,0) -> 6 | K28: archaeo_armor_m2 | L28: =(ROW()-ROW(L$27)+1)*首页!$F$13 -> 960 | M28: archaeo_alloys_cost_m2 | N28: =ROUNDUP((ROW()-ROW(N$27)+1)*首页!$H$13*首页!$L$13,0) -> 88 | O28: =首页!$K$13 -> 20
A29: 3 | B29: 中型 | C29: MEDIUM_ARCHAEO_ARMOR_3 | D29: archaeo_shield_m3 | E29: =(ROW()-ROW(E$27)+1)*首页!$B$13 -> 900 | F29: archaeo_shield_m3_buff | G29: =(ROW()-ROW(G$27)+1)*首页!$C$13 -> 900 | H29: =E29+G29 -> 1800 | I29: archaeo_shield_regen_m3 | J29: =ROUNDUP(H29/200,0) -> 9 | K29: archaeo_armor_m3 | L29: =(ROW()-ROW(L$27)+1)*首页!$F$13 -> 1440 | M29: archaeo_alloys_cost_m3 | N29: =ROUNDUP((ROW()-ROW(N$27)+1)*首页!$H$13*首页!$L$13,0) -> 132 | O29: =首页!$K$13 -> 20
A30: 4 | B30: 中型 | C30: MEDIUM_ARCHAEO_ARMOR_4 | D30: archaeo_shield_m4 | E30: =(ROW()-ROW(E$27)+1)*首页!$B$13 -> 1200 | F30: archaeo_shield_m4_buff | G30: =(ROW()-ROW(G$27)+1)*首页!$C$13 -> 1200 | H30: =E30+G30 -> 2400 | I30: archaeo_shield_regen_m4 | J30: =ROUNDUP(H30/200,0) -> 12 | K30: archaeo_armor_m4 | L30: =(ROW()-ROW(L$27)+1)*首页!$F$13 -> 1920 | M30: archaeo_alloys_cost_m4 | N30: =ROUNDUP((ROW()-ROW(N$27)+1)*首页!$H$13*首页!$L$13,0) -> 176 | O30: =首页!$K$13 -> 20
A31: 5 | B31: 中型 | C31: MEDIUM_ARCHAEO_ARMOR_5 | D31: archaeo_shield_m5 | E31: =(ROW()-ROW(E$27)+1)*首页!$B$13 -> 1500 | F31: archaeo_shield_m5_buff | G31: =(ROW()-ROW(G$27)+1)*首页!$C$13 -> 1500 | H31: =E31+G31 -> 3000 | I31: archaeo_shield_regen_m5 | J31: =ROUNDUP(H31/200,0) -> 15 | K31: archaeo_armor_m5 | L31: =(ROW()-ROW(L$27)+1)*首页!$F$13 -> 2400 | M31: archaeo_alloys_cost_m5 | N31: =ROUNDUP((ROW()-ROW(N$27)+1)*首页!$H$13*首页!$L$13,0) -> 220 | O31: =首页!$K$13 -> 20
A32: 6 | B32: 中型 | C32: MEDIUM_ARCHAEO_ARMOR_6 | D32: archaeo_shield_m6 | E32: =(ROW()-ROW(E$27)+1)*首页!$B$13 -> 1800 | F32: archaeo_shield_m6_buff | G32: =(ROW()-ROW(G$27)+1)*首页!$C$13 -> 1800 | H32: =E32+G32 -> 3600 | I32: archaeo_shield_regen_m6 | J32: =ROUNDUP(H32/200,0) -> 18 | K32: archaeo_armor_m6 | L32: =(ROW()-ROW(L$27)+1)*首页!$F$13 -> 2880 | M32: archaeo_alloys_cost_m6 | N32: =ROUNDUP((ROW()-ROW(N$27)+1)*首页!$H$13*首页!$L$13,0) -> 264 | O32: =首页!$K$13 -> 20
A33: 7 | B33: 中型 | C33: MEDIUM_ARCHAEO_ARMOR_7 | D33: archaeo_shield_m7 | E33: =(ROW()-ROW(E$27)+1)*首页!$B$13 -> 2100 | F33: archaeo_shield_m7_buff | G33: =(ROW()-ROW(G$27)+1)*首页!$C$13 -> 2100 | H33: =E33+G33 -> 4200 | I33: archaeo_shield_regen_m7 | J33: =ROUNDUP(H33/200,0) -> 21 | K33: archaeo_armor_m7 | L33: =(ROW()-ROW(L$27)+1)*首页!$F$13 -> 3360 | M33: archaeo_alloys_cost_m7 | N33: =ROUNDUP((ROW()-ROW(N$27)+1)*首页!$H$13*首页!$L$13,0) -> 308 | O33: =首页!$K$13 -> 20
A34: 8 | B34: 中型 | C34: MEDIUM_ARCHAEO_ARMOR_8 | D34: archaeo_shield_m8 | E34: =(ROW()-ROW(E$27)+1)*首页!$B$13 -> 2400 | F34: archaeo_shield_m8_buff | G34: =(ROW()-ROW(G$27)+1)*首页!$C$13 -> 2400 | H34: =E34+G34 -> 4800 | I34: archaeo_shield_regen_m8 | J34: =ROUNDUP(H34/200,0) -> 24 | K34: archaeo_armor_m8 | L34: =(ROW()-ROW(L$27)+1)*首页!$F$13 -> 3840 | M34: archaeo_alloys_cost_m8 | N34: =ROUNDUP((ROW()-ROW(N$27)+1)*首页!$H$13*首页!$L$13,0) -> 352 | O34: =首页!$K$13 -> 20
A35: 9 | B35: 中型 | C35: MEDIUM_ARCHAEO_ARMOR_9 | D35: archaeo_shield_m9 | E35: =(ROW()-ROW(E$27)+1)*首页!$B$13 -> 2700 | F35: archaeo_shield_m9_buff | G35: =(ROW()-ROW(G$27)+1)*首页!$C$13 -> 2700 | H35: =E35+G35 -> 5400 | I35: archaeo_shield_regen_m9 | J35: =ROUNDUP(H35/200,0) -> 27 | K35: archaeo_armor_m9 | L35: =(ROW()-ROW(L$27)+1)*首页!$F$13 -> 4320 | M35: archaeo_alloys_cost_m9 | N35: =ROUNDUP((ROW()-ROW(N$27)+1)*首页!$H$13*首页!$L$13,0) -> 396 | O35: =首页!$K$13 -> 20
A36: 10 | B36: 中型 | C36: MEDIUM_ARCHAEO_ARMOR_10 | D36: archaeo_shield_m10 | E36: =(ROW()-ROW(E$27)+1)*首页!$B$13 -> 3000 | F36: archaeo_shield_m10_buff | G36: =(ROW()-ROW(G$27)+1)*首页!$C$13 -> 3000 | H36: =E36+G36 -> 6000 | I36: archaeo_shield_regen_m10 | J36: =ROUNDUP(H36/200,0) -> 30 | K36: archaeo_armor_m10 | L36: =(ROW()-ROW(L$27)+1)*首页!$F$13 -> 4800 | M36: archaeo_alloys_cost_m10 | N36: =ROUNDUP((ROW()-ROW(N$27)+1)*首页!$H$13*首页!$L$13,0) -> 440 | O36: =首页!$K$13 -> 20
A37: 11 | B37: 中型 | C37: MEDIUM_ARCHAEO_ARMOR_11 | D37: archaeo_shield_m11 | E37: =(ROW()-ROW(E$27)+1)*首页!$B$13 -> 3300 | F37: archaeo_shield_m11_buff | G37: =(ROW()-ROW(G$27)+1)*首页!$C$13 -> 3300 | H37: =E37+G37 -> 6600 | I37: archaeo_shield_regen_m11 | J37: =ROUNDUP(H37/200,0) -> 33 | K37: archaeo_armor_m11 | L37: =(ROW()-ROW(L$27)+1)*首页!$F$13 -> 5280 | M37: archaeo_alloys_cost_m11 | N37: =ROUNDUP((ROW()-ROW(N$27)+1)*首页!$H$13*首页!$L$13,0) -> 484 | O37: =首页!$K$13 -> 20
A38: 12 | B38: 中型 | C38: MEDIUM_ARCHAEO_ARMOR_12 | D38: archaeo_shield_m12 | E38: =(ROW()-ROW(E$27)+1)*首页!$B$13 -> 3600 | F38: archaeo_shield_m12_buff | G38: =(ROW()-ROW(G$27)+1)*首页!$C$13 -> 3600 | H38: =E38+G38 -> 7200 | I38: archaeo_shield_regen_m12 | J38: =ROUNDUP(H38/200,0) -> 36 | K38: archaeo_armor_m12 | L38: =(ROW()-ROW(L$27)+1)*首页!$F$13 -> 5760 | M38: archaeo_alloys_cost_m12 | N38: =ROUNDUP((ROW()-ROW(N$27)+1)*首页!$H$13*首页!$L$13,0) -> 528 | O38: =首页!$K$13 -> 20
A39: 13 | B39: 中型 | C39: MEDIUM_ARCHAEO_ARMOR_13 | D39: archaeo_shield_m13 | E39: =(ROW()-ROW(E$27)+1)*首页!$B$13 -> 3900 | F39: archaeo_shield_m13_buff | G39: =(ROW()-ROW(G$27)+1)*首页!$C$13 -> 3900 | H39: =E39+G39 -> 7800 | I39: archaeo_shield_regen_m13 | J39: =ROUNDUP(H39/200,0) -> 39 | K39: archaeo_armor_m13 | L39: =(ROW()-ROW(L$27)+1)*首页!$F$13 -> 6240 | M39: archaeo_alloys_cost_m13 | N39: =ROUNDUP((ROW()-ROW(N$27)+1)*首页!$H$13*首页!$L$13,0) -> 572 | O39: =首页!$K$13 -> 20
A40: 14 | B40: 中型 | C40: MEDIUM_ARCHAEO_ARMOR_14 | D40: archaeo_shield_m14 | E40: =(ROW()-ROW(E$27)+1)*首页!$B$13 -> 4200 | F40: archaeo_shield_m14_buff | G40: =(ROW()-ROW(G$27)+1)*首页!$C$13 -> 4200 | H40: =E40+G40 -> 8400 | I40: archaeo_shield_regen_m14 | J40: =ROUNDUP(H40/200,0) -> 42 | K40: archaeo_armor_m14 | L40: =(ROW()-ROW(L$27)+1)*首页!$F$13 -> 6720 | M40: archaeo_alloys_cost_m14 | N40: =ROUNDUP((ROW()-ROW(N$27)+1)*首页!$H$13*首页!$L$13,0) -> 616 | O40: =首页!$K$13 -> 20
... A51: 25 | B51: 中型 | C51: MEDIUM_ARCHAEO_ARMOR_25 | D51: archaeo_shield_m25 | E51: =(ROW()-ROW(E$27)+1)*首页!$B$13 -> 7500 | F51: archaeo_shield_m25_buff | G51: =(ROW()-ROW(G$27)+1)*首页!$C$13 -> 7500 | H51: =E51+G51 -> 15000 | I51: archaeo_shield_regen_m25 | J51: =ROUNDUP(H51/200,0) -> 75 | K51: archaeo_armor_m25 | L51: =(ROW()-ROW(L$27)+1)*首页!$F$13 -> 12000 | M51: archaeo_alloys_cost_m25 | N51: =ROUNDUP((ROW()-ROW(N$27)+1)*首页!$H$13*首页!$L$13,0) -> 1100 | O51: =首页!$K$13 -> 20
A53: 级别 | B53: 尺寸 | C53: 游戏key | D53: 基础护盾承受值 | E53: 数值 | F53: 基础护盾承受值 | G53: 数值 | H53: 总护盾值 | I53: 护盾每日回复 | J53: 数值 | K53: 装甲值 | L53: 数值 | M53: 合金花费 | N53: 数值 | O53: 稀有文物花费
A54: 2 | B54: 大型 | C54: LARGE_ARCHAEO_ARMOR_2 | D54: archaeo_shield_l2 | E54: =(ROW()-ROW(E$53)+1)*首页!$B$14 -> 1800 | F54: archaeo_shield_l2_buff | G54: =(ROW()-ROW(G$53)+1)*首页!$C$14 -> 1800 | H54: =E54+G54 -> 3600 | I54: archaeo_shield_regen_l2 | J54: =ROUNDUP(H54/首页!$E$14,0) -> 18 | K54: archaeo_armor_l2 | L54: =(ROW()-ROW(L$53)+1)*首页!$F$14 -> 2880 | M54: archaeo_alloys_cost_l2 | N54: =(ROW()-ROW(N$53)+1)*首页!$H$14*首页!$L$14 -> 220 | O54: =首页!$K$14 -> 50
A55: 3 | B55: 大型 | C55: LARGE_ARCHAEO_ARMOR_3 | D55: archaeo_shield_l3 | E55: =(ROW()-ROW(E$53)+1)*首页!$B$14 -> 2700 | F55: archaeo_shield_l3_buff | G55: =(ROW()-ROW(G$53)+1)*首页!$C$14 -> 2700 | H55: =E55+G55 -> 5400 | I55: archaeo_shield_regen_l3 | J55: =ROUNDUP(H55/首页!$E$14,0) -> 27 | K55: archaeo_armor_l3 | L55: =(ROW()-ROW(L$53)+1)*首页!$F$14 -> 4320 | M55: archaeo_alloys_cost_l3 | N55: =(ROW()-ROW(N$53)+1)*首页!$H$14*首页!$L$14 -> 330 | O55: =首页!$K$14 -> 50
A56: 4 | B56: 大型 | C56: LARGE_ARCHAEO_ARMOR_4 | D56: archaeo_shield_l4 | E56: =(ROW()-ROW(E$53)+1)*首页!$B$14 -> 3600 | F56: archaeo_shield_l4_buff | G56: =(ROW()-ROW(G$53)+1)*首页!$C$14 -> 3600 | H56: =E56+G56 -> 7200 | I56: archaeo_shield_regen_l4 | J56: =ROUNDUP(H56/首页!$E$14,0) -> 36 | K56: archaeo_armor_l4 | L56: =(ROW()-ROW(L$53)+1)*首页!$F$14 -> 5760 | M56: archaeo_alloys_cost_l4 | N56: =(ROW()-ROW(N$53)+1)*首页!$H$14*首页!$L$14 -> 440 | O56: =首页!$K$14 -> 50
A57: 5 | B57: 大型 | C57: LARGE_ARCHAEO_ARMOR_5 | D57: archaeo_shield_l5 | E57: =(ROW()-ROW(E$53)+1)*首页!$B$14 -> 4500 | F57: archaeo_shield_l5_buff | G57: =(ROW()-ROW(G$53)+1)*首页!$C$14 -> 4500 | H57: =E57+G57 -> 9000 | I57: archaeo_shield_regen_l5 | J57: =ROUNDUP(H57/首页!$E$14,0) -> 45 | K57: archaeo_armor_l5 | L57: =(ROW()-ROW(L$53)+1)*首页!$F$14 -> 7200 | M57: archaeo_alloys_cost_l5 | N57: =(ROW()-ROW(N$53)+1)*首页!$H$14*首页!$L$14 -> 550 | O57: =首页!$K$14 -> 50
A58: 6 | B58: 大型 | C58: LARGE_ARCHAEO_ARMOR_6 | D58: archaeo_shield_l6 | E58: =(ROW()-ROW(E$53)+1)*首页!$B$14 -> 5400 | F58: archaeo_shield_l6_buff | G58: =(ROW()-ROW(G$53)+1)*首页!$C$14 -> 5400 | H58: =E58+G58 -> 10800 | I58: archaeo_shield_regen_l6 | J58: =ROUNDUP(H58/首页!$E$14,0) -> 54 | K58: archaeo_armor_l6 | L58: =(ROW()-ROW(L$53)+1)*首页!$F$14 -> 8640 | M58: archaeo_alloys_cost_l6 | N58: =(ROW()-ROW(N$53)+1)*首页!$H$14*首页!$L$14 -> 660 | O58: =首页!$K$14 -> 50
A59: 7 | B59: 大型 | C59: LARGE_ARCHAEO_ARMOR_7 | D59: archaeo_shield_l7 | E59: =(ROW()-ROW(E$53)+1)*首页!$B$14 -> 6300 | F59: archaeo_shield_l7_buff | G59: =(ROW()-ROW(G$53)+1)*首页!$C$14 -> 6300 | H59: =E59+G59 -> 12600 | I59: archaeo_shield_regen_l7 | J59: =ROUNDUP(H59/首页!$E$14,0) -> 63 | K59: archaeo_armor_l7 | L59: =(ROW()-ROW(L$53)+1)*首页!$F$14 -> 10080 | M59: archaeo_alloys_cost_l7 | N59: =(ROW()-ROW(N$53)+1)*首页!$H$14*首页!$L$14 -> 770 | O59: =首页!$K$14 -> 50
A60: 8 | B60: 大型 | C60: LARGE_ARCHAEO_ARMOR_8 | D60: archaeo_shield_l8 | E60: =(ROW()-ROW(E$53)+1)*首页!$B$14 -> 7200 | F60: archaeo_shield_l8_buff | G60: =(ROW()-ROW(G$53)+1)*首页!$C$14 -> 7200 | H60: =E60+G60 -> 14400 | I60: archaeo_shield_regen_l8 | J60: =ROUNDUP(H60/首页!$E$14,0) -> 72 | K60: archaeo_armor_l8 | L60: =(ROW()-ROW(L$53)+1)*首页!$F$14 -> 11520 | M60: archaeo_alloys_cost_l8 | N60: =(ROW()-ROW(N$53)+1)*首页!$H$14*首页!$L$14 -> 880 | O60: =首页!$K$14 -> 50
A61: 9 | B61: 大型 | C61: LARGE_ARCHAEO_ARMOR_9 | D61: archaeo_shield_l9 | E61: =(ROW()-ROW(E$53)+1)*首页!$B$14 -> 8100 | F61: archaeo_shield_l9_buff | G61: =(ROW()-ROW(G$53)+1)*首页!$C$14 -> 8100 | H61: =E61+G61 -> 16200 | I61: archaeo_shield_regen_l9 | J61: =ROUNDUP(H61/首页!$E$14,0) -> 81 | K61: archaeo_armor_l9 | L61: =(ROW()-ROW(L$53)+1)*首页!$F$14 -> 12960 | M61: archaeo_alloys_cost_l9 | N61: =(ROW()-ROW(N$53)+1)*首页!$H$14*首页!$L$14 -> 990 | O61: =首页!$K$14 -> 50
A62: 10 | B62: 大型 | C62: LARGE_ARCHAEO_ARMOR_10 | D62: archaeo_shield_l10 | E62: =(ROW()-ROW(E$53)+1)*首页!$B$14 -> 9000 | F62: archaeo_shield_l10_buff | G62: =(ROW()-ROW(G$53)+1)*首页!$C$14 -> 9000 | H62: =E62+G62 -> 18000 | I62: archaeo_shield_regen_l10 | J62: =ROUNDUP(H62/首页!$E$14,0) -> 90 | K62: archaeo_armor_l10 | L62: =(ROW()-ROW(L$53)+1)*首页!$F$14 -> 14400 | M62: archaeo_alloys_cost_l10 | N62: =(ROW()-ROW(N$53)+1)*首页!$H$14*首页!$L$14 -> 1100 | O62: =首页!$K$14 -> 50
A63: 11 | B63: 大型 | C63: LARGE_ARCHAEO_ARMOR_11 | D63: archaeo_shield_l11 | E63: =(ROW()-ROW(E$53)+1)*首页!$B$14 -> 9900 | F63: archaeo_shield_l11_buff | G63: =(ROW()-ROW(G$53)+1)*首页!$C$14 -> 9900 | H63: =E63+G63 -> 19800 | I63: archaeo_shield_regen_l11 | J63: =ROUNDUP(H63/首页!$E$14,0) -> 99 | K63: archaeo_armor_l11 | L63: =(ROW()-ROW(L$53)+1)*首页!$F$14 -> 15840 | M63: archaeo_alloys_cost_l11 | N63: =(ROW()-ROW(N$53)+1)*首页!$H$14*首页!$L$14 -> 1210 | O63: =首页!$K$14 -> 50
...

Sheet 脉冲甲壳
